Workbook
Name _xleta_N: none
Name _xleta_N: none
Name _xleta_ROUNDUP: none
Name _xleta_ROUNDUP: none
Name _xleta_TEXT: none
Name _xleta_TEXT: none
Name _xlfn_SINGLE: none
Name _xlfn_SINGLE: none
Name _xlfn_XLOOKUP: none
Name _xlfn_XLOOKUP: none
Name Fluxo: LAMPADAS!$A$3:$D$14
Name Fluxo_Lampadas: LAMPADAS!$A$3:$D$14

Sheet AMBIENTES
C1: ESTUDO DE CARGAS — LUMINOTECNICO
A2: GUID | B2: ID | C2: AMBIENTE | D2: ATIVIDADE NBR | E2: AREA | F2: PERIMETRO | G2: COMPRIMENTO | H2: LARGURA | I2: ALTURA LUMINARIA | J2: ILUMINANCIA | K2: INDICE DO LOCAL | L2: LUMINARIA | M2: FLUXO LUMINOSO | N2: FU | O2: FM | P2: N CALC | Q2: N ADOTADO | R2: POTENCIA | S2: CARGA ILUM | T2: ANALISE LUX | U2: ANALISE LUMINARIAS | V2: LUX REAL
D3: 8995-1 / 5413 | E3: m2 | F3: m | G3: m | H3: m | I3: m | J3: lux (NBR) | K3: K | L3: selecione | M3: lm | N3: fat. utilizacao | O3: fat. manutencao | P3: luminarias | Q3: luminarias | R3: W/lum | S3: W | T3: OK/INSUF/ACIMA | U3: ajuste | V3: lux adotado | W3: LUX IDEAL | X3: LUX MAX | Y3: LUX MINIMO
E4: =IF(G4*H4=0,"",ROUND(G4*H4,2)) | J4: =IFERROR(VLOOKUP(D4,NBR!$C:$E,3,0),"") | K4: =IF(AND(E4<>"",F4<>"",I4<>"", F4<>0, I4<>0), E4/(F4/2*I4), "") | M4: =IFERROR(VLOOKUP(L4,#REF!,2,0),"") | P4: =IF(AND(E4<>"",J4<>"",M4<>"",N4<>"",O4<>"",N4<>0,O4<>0), ROUNDUP((E4*J4)/(M4*N4*O4),0), "") | R4: =IFERROR(VLOOKUP(L4,#REF!,4,0),"")
J5: =IFERROR(VLOOKUP(D5,NBR!$C:$E,3,0),"") | K5: =IF(E5*F5*I5=0,"",(4*E5)/((F5)*I5)) | M5: =IFERROR(VLOOKUP(L5,LAMPADAS!$A:$B,2,0),"") | P5: =IF(AND(E5<>"",J5<>"",M5<>"",N5<>"",O5<>"",N5<>0,O5<>0), ROUNDUP((E5*J5)/(M5*N5*O5),0), "") | R5: =IFERROR(VLOOKUP(L5,LAMPADAS!$A:$D,4,0),"") | S5: =IF(AND(Q5<>"",R5<>""),Q5*R5,"") | T5: =IF(AND(E5<>"",J5<>"",Q5<>"",M5<>"",N5<>"",O5<>""),IF(E5*J5=0,"—",IF((Q5*M5*N5*O5)/E5<J5*0.9,"INSUFICIENTE -"&TEXT(ABS(((Q5*M5*N5*O5)/E5-J5)/J5)*100,"0")&"%",IF((Q5*M5*N5*O5)/E5>J5*1.31,"ACIMA +"&TEXT((((Q5*M5*N5*O5)/E5-J5)/J5)*100,"0")&"%","OK "&IF((Q5*M5*N5*O5)/E5>=J5,"+","")&TEXT((((Q5*M5*N5*O5)/E5-J5)/J5)*100,"0")&"%"))),"") | U5: =IF(E5*J5*M5=0,"",IF((Q5*M5*N5*O5)/E5<IF(IFERROR(VLOOKUP(D5,NBR!$C:$D,2,0),J5)=IFERROR(VLOOKUP(D5,NBR!$C:$F,4,0),J5),J5*0.9,IFERROR(VLOOKUP(D5,NBR!$C:$D,2,0),J5*0.9)),"COLOCAR +"&TEXT(ROUNDUP((E5*J5)/(M5*N5*O5),0)-Q5,"0")&" luminaria(s)",IF((Q5*M5*N5*O5)/E5>IF(IFERROR(VLOOKUP(D5,NBR!$C:$F,4,0),J5)=IFERROR(VLOOKUP(D5,NBR!$C:$D,2,0),J5),J5*1.2,IFERROR(VLOOKUP(D5,NBR!$C:$F,4,0),J5*1.2)),IF(Q5=1,"Reduzir potencia luminaria","RETIRAR -"&TEXT(Q5-ROUNDUP((E5*IF(IFERROR(VLOOKUP(D5,NBR!$C:$F,4,0),J5)=J5,J5*1.2,IFERROR(VLOOKUP(D5,NBR!$C:$F,4,0),J5*1.2)))/(M5*N5*O5),0),"0")&" luminaria(s)"),"OK"))) -> #VALUE! | V5: =IF(E5*M5=0,"",ROUND((Q5*M5*N5*O5)/E5,0)) -> #VALUE! | W5: =IFERROR(VLOOKUP(D5,NBR!$C:$F,3,0),"") | X5: =IFERROR(VLOOKUP(D5,NBR!$C:$F,4,0),"") | Y5: =IFERROR(VLOOKUP(D5,NBR!$C:$F,2,0),"")
J6: =IFERROR(VLOOKUP(D6,NBR!$C:$E,3,0),"") | K6: =IF(E6*F6*I6=0,"",(4*E6)/((F6)*I6)) | M6: =IFERROR(VLOOKUP(L6,LAMPADAS!$A:$B,2,0),"") | P6: =IF(AND(E6<>"",J6<>"",M6<>"",N6<>"",O6<>"",N6<>0,O6<>0), ROUNDUP((E6*J6)/(M6*N6*O6),0), "") | R6: =IFERROR(VLOOKUP(L6,LAMPADAS!$A:$D,4,0),"") | S6: =IF(AND(Q6<>"",R6<>""),Q6*R6,"") | T6: =IF(E6*J6=0,"—",IF((Q6*M6*N6*O6)/E6<J6*0.9,"INSUFICIENTE -"&TEXT(ABS(((Q6*M6*N6*O6)/E6-J6)/J6)*100,"0")&"%",IF((Q6*M6*N6*O6)/E6>J6*1.31,"ACIMA +"&TEXT((((Q6*M6*N6*O6)/E6-J6)/J6)*100,"0")&"%","OK "&IF((Q6*M6*N6*O6)/E6>=J6,"+","")&TEXT((((Q6*M6*N6*O6)/E6-J6)/J6)*100,"0")&"%"))) -> #VALUE! | U6: =IF(E6*J6*M6=0,"",IF((Q6*M6*N6*O6)/E6<IF(IFERROR(VLOOKUP(D6,NBR!$C:$D,2,0),J6)=IFERROR(VLOOKUP(D6,NBR!$C:$F,4,0),J6),J6*0.9,IFERROR(VLOOKUP(D6,NBR!$C:$D,2,0),J6*0.9)),"COLOCAR +"&TEXT(ROUNDUP((E6*J6)/(M6*N6*O6),0)-Q6,"0")&" luminaria(s)",IF((Q6*M6*N6*O6)/E6>IF(IFERROR(VLOOKUP(D6,NBR!$C:$F,4,0),J6)=IFERROR(VLOOKUP(D6,NBR!$C:$D,2,0),J6),J6*1.2,IFERROR(VLOOKUP(D6,NBR!$C:$F,4,0),J6*1.2)),IF(Q6=1,"Reduzir potencia luminaria","RETIRAR -"&TEXT(Q6-ROUNDUP((E6*IF(IFERROR(VLOOKUP(D6,NBR!$C:$F,4,0),J6)=J6,J6*1.2,IFERROR(VLOOKUP(D6,NBR!$C:$F,4,0),J6*1.2)))/(M6*N6*O6),0),"0")&" luminaria(s)"),"OK"))) -> #VALUE! | V6: =IF(E6*M6=0,"",ROUND((Q6*M6*N6*O6)/E6,0)) -> #VALUE! | W6: =IFERROR(VLOOKUP(D6,NBR!$C:$F,3,0),"") | X6: =IFERROR(VLOOKUP(D6,NBR!$C:$F,4,0),"") | Y6: =IFERROR(VLOOKUP(D6,NBR!$C:$F,2,0),"")
J7: =IFERROR(VLOOKUP(D7,NBR!$C:$E,3,0),"") | K7: =IF(E7*F7*I7=0,"",(4*E7)/((F7)*I7)) | M7: =IFERROR(VLOOKUP(L7,LAMPADAS!$A:$B,2,0),"") | P7: =IF(AND(E7<>"",J7<>"",M7<>"",N7<>"",O7<>"",N7<>0,O7<>0), ROUNDUP((E7*J7)/(M7*N7*O7),0), "") | R7: =IFERROR(VLOOKUP(L7,LAMPADAS!$A:$D,4,0),"") | S7: =IF(AND(Q7<>"",R7<>""),Q7*R7,"") | T7: =IF(E7*J7=0,"—",IF((Q7*M7*N7*O7)/E7<J7*0.9,"INSUFICIENTE -"&TEXT(ABS(((Q7*M7*N7*O7)/E7-J7)/J7)*100,"0")&"%",IF((Q7*M7*N7*O7)/E7>J7*1.31,"ACIMA +"&TEXT((((Q7*M7*N7*O7)/E7-J7)/J7)*100,"0")&"%","OK "&IF((Q7*M7*N7*O7)/E7>=J7,"+","")&TEXT((((Q7*M7*N7*O7)/E7-J7)/J7)*100,"0")&"%"))) -> #VALUE! | U7: =IF(E7*J7*M7=0,"",IF((Q7*M7*N7*O7)/E7<IF(IFERROR(VLOOKUP(D7,NBR!$C:$D,2,0),J7)=IFERROR(VLOOKUP(D7,NBR!$C:$F,4,0),J7),J7*0.9,IFERROR(VLOOKUP(D7,NBR!$C:$D,2,0),J7*0.9)),"COLOCAR +"&TEXT(ROUNDUP((E7*J7)/(M7*N7*O7),0)-Q7,"0")&" luminaria(s)",IF((Q7*M7*N7*O7)/E7>IF(IFERROR(VLOOKUP(D7,NBR!$C:$F,4,0),J7)=IFERROR(VLOOKUP(D7,NBR!$C:$D,2,0),J7),J7*1.2,IFERROR(VLOOKUP(D7,NBR!$C:$F,4,0),J7*1.2)),IF(Q7=1,"Reduzir potencia luminaria","RETIRAR -"&TEXT(Q7-ROUNDUP((E7*IF(IFERROR(VLOOKUP(D7,NBR!$C:$F,4,0),J7)=J7,J7*1.2,IFERROR(VLOOKUP(D7,NBR!$C:$F,4,0),J7*1.2)))/(M7*N7*O7),0),"0")&" luminaria(s)"),"OK"))) -> #VALUE! | V7: =IF(E7*M7=0,"",ROUND((Q7*M7*N7*O7)/E7,0)) -> #VALUE! | W7: =IFERROR(VLOOKUP(D7,NBR!$C:$F,3,0),"") | X7: =IFERROR(VLOOKUP(D7,NBR!$C:$F,4,0),"") | Y7: =IFERROR(VLOOKUP(D7,NBR!$C:$F,2,0),"")
J8: =IFERROR(VLOOKUP(D8,NBR!$C:$E,3,0),"") | K8: =IF(E8*F8*I8=0,"",(4*E8)/((F8)*I8)) | M8: =IFERROR(VLOOKUP(L8,LAMPADAS!$A:$B,2,0),"") | P8: =IF(AND(E8<>"",J8<>"",M8<>"",N8<>"",O8<>"",N8<>0,O8<>0), ROUNDUP((E8*J8)/(M8*N8*O8),0), "") | R8: =IFERROR(VLOOKUP(L8,LAMPADAS!$A:$D,4,0),"") | S8: =IF(AND(Q8<>"",R8<>""),Q8*R8,"") | T8: =IF(E8*J8=0,"—",IF((Q8*M8*N8*O8)/E8<J8*0.9,"INSUFICIENTE -"&TEXT(ABS(((Q8*M8*N8*O8)/E8-J8)/J8)*100,"0")&"%",IF((Q8*M8*N8*O8)/E8>J8*1.31,"ACIMA +"&TEXT((((Q8*M8*N8*O8)/E8-J8)/J8)*100,"0")&"%","OK "&IF((Q8*M8*N8*O8)/E8>=J8,"+","")&TEXT((((Q8*M8*N8*O8)/E8-J8)/J8)*100,"0")&"%"))) -> #VALUE! | U8: =IF(E8*J8*M8=0,"",IF((Q8*M8*N8*O8)/E8<IF(IFERROR(VLOOKUP(D8,NBR!$C:$D,2,0),J8)=IFERROR(VLOOKUP(D8,NBR!$C:$F,4,0),J8),J8*0.9,IFERROR(VLOOKUP(D8,NBR!$C:$D,2,0),J8*0.9)),"COLOCAR +"&TEXT(ROUNDUP((E8*J8)/(M8*N8*O8),0)-Q8,"0")&" luminaria(s)",IF((Q8*M8*N8*O8)/E8>IF(IFERROR(VLOOKUP(D8,NBR!$C:$F,4,0),J8)=IFERROR(VLOOKUP(D8,NBR!$C:$D,2,0),J8),J8*1.2,IFERROR(VLOOKUP(D8,NBR!$C:$F,4,0),J8*1.2)),IF(Q8=1,"Reduzir potencia luminaria","RETIRAR -"&TEXT(Q8-ROUNDUP((E8*IF(IFERROR(VLOOKUP(D8,NBR!$C:$F,4,0),J8)=J8,J8*1.2,IFERROR(VLOOKUP(D8,NBR!$C:$F,4,0),J8*1.2)))/(M8*N8*O8),0),"0")&" luminaria(s)"),"OK"))) -> #VALUE! | V8: =IF(E8*M8=0,"",ROUND((Q8*M8*N8*O8)/E8,0)) -> #VALUE! | W8: =IFERROR(VLOOKUP(D8,NBR!$C:$F,3,0),"") | X8: =IFERROR(VLOOKUP(D8,NBR!$C:$F,4,0),"") | Y8: =IFERROR(VLOOKUP(D8,NBR!$C:$F,2,0),"")
J9: =IFERROR(VLOOKUP(D9,NBR!$C:$E,3,0),"") | K9: =IF(E9*F9*I9=0,"",(4*E9)/((F9)*I9)) | M9: =IFERROR(VLOOKUP(L9,LAMPADAS!$A:$B,2,0),"") | P9: =IF(AND(E9<>"",J9<>"",M9<>"",N9<>"",O9<>"",N9<>0,O9<>0), ROUNDUP((E9*J9)/(M9*N9*O9),0), "") | R9: =IFERROR(VLOOKUP(L9,LAMPADAS!$A:$D,4,0),"") | S9: =IF(AND(Q9<>"",R9<>""),Q9*R9,"") | T9: =IF(E9*J9=0,"—",IF((Q9*M9*N9*O9)/E9<J9*0.9,"INSUFICIENTE -"&TEXT(ABS(((Q9*M9*N9*O9)/E9-J9)/J9)*100,"0")&"%",IF((Q9*M9*N9*O9)/E9>J9*1.31,"ACIMA +"&TEXT((((Q9*M9*N9*O9)/E9-J9)/J9)*100,"0")&"%","OK "&IF((Q9*M9*N9*O9)/E9>=J9,"+","")&TEXT((((Q9*M9*N9*O9)/E9-J9)/J9)*100,"0")&"%"))) -> #VALUE! | U9: =IF(E9*J9*M9=0,"",IF((Q9*M9*N9*O9)/E9<IF(IFERROR(VLOOKUP(D9,NBR!$C:$D,2,0),J9)=IFERROR(VLOOKUP(D9,NBR!$C:$F,4,0),J9),J9*0.9,IFERROR(VLOOKUP(D9,NBR!$C:$D,2,0),J9*0.9)),"COLOCAR +"&TEXT(ROUNDUP((E9*J9)/(M9*N9*O9),0)-Q9,"0")&" luminaria(s)",IF((Q9*M9*N9*O9)/E9>IF(IFERROR(VLOOKUP(D9,NBR!$C:$F,4,0),J9)=IFERROR(VLOOKUP(D9,NBR!$C:$D,2,0),J9),J9*1.2,IFERROR(VLOOKUP(D9,NBR!$C:$F,4,0),J9*1.2)),IF(Q9=1,"Reduzir potencia luminaria","RETIRAR -"&TEXT(Q9-ROUNDUP((E9*IF(IFERROR(VLOOKUP(D9,NBR!$C:$F,4,0),J9)=J9,J9*1.2,IFERROR(VLOOKUP(D9,NBR!$C:$F,4,0),J9*1.2)))/(M9*N9*O9),0),"0")&" luminaria(s)"),"OK"))) -> #VALUE! | V9: =IF(E9*M9=0,"",ROUND((Q9*M9*N9*O9)/E9,0)) -> #VALUE! | W9: =IFERROR(VLOOKUP(D9,NBR!$C:$F,3,0),"") | X9: =IFERROR(VLOOKUP(D9,NBR!$C:$F,4,0),"") | Y9: =IFERROR(VLOOKUP(D9,NBR!$C:$F,2,0),"")
J10: =IFERROR(VLOOKUP(D10,NBR!$C:$E,3,0),"") | K10: =IF(E10*F10*I10=0,"",(4*E10)/((F10)*I10)) | M10: =IFERROR(VLOOKUP(L10,LAMPADAS!$A:$B,2,0),"") | P10: =IF(AND(E10<>"",J10<>"",M10<>"",N10<>"",O10<>"",N10<>0,O10<>0), ROUNDUP((E10*J10)/(M10*N10*O10),0), "") | R10: =IFERROR(VLOOKUP(L10,LAMPADAS!$A:$D,4,0),"") | S10: =IF(AND(Q10<>"",R10<>""),Q10*R10,"") | T10: =IF(E10*J10=0,"—",IF((Q10*M10*N10*O10)/E10<J10*0.9,"INSUFICIENTE -"&TEXT(ABS(((Q10*M10*N10*O10)/E10-J10)/J10)*100,"0")&"%",IF((Q10*M10*N10*O10)/E10>J10*1.31,"ACIMA +"&TEXT((((Q10*M10*N10*O10)/E10-J10)/J10)*100,"0")&"%","OK "&IF((Q10*M10*N10*O10)/E10>=J10,"+","")&TEXT((((Q10*M10*N10*O10)/E10-J10)/J10)*100,"0")&"%"))) -> #VALUE! | U10: =IF(E10*J10*M10=0,"",IF((Q10*M10*N10*O10)/E10<IF(IFERROR(VLOOKUP(D10,NBR!$C:$D,2,0),J10)=IFERROR(VLOOKUP(D10,NBR!$C:$F,4,0),J10),J10*0.9,IFERROR(VLOOKUP(D10,NBR!$C:$D,2,0),J10*0.9)),"COLOCAR +"&TEXT(ROUNDUP((E10*J10)/(M10*N10*O10),0)-Q10,"0")&" luminaria(s)",IF((Q10*M10*N10*O10)/E10>IF(IFERROR(VLOOKUP(D10,NBR!$C:$F,4,0),J10)=IFERROR(VLOOKUP(D10,NBR!$C:$D,2,0),J10),J10*1.2,IFERROR(VLOOKUP(D10,NBR!$C:$F,4,0),J10*1.2)),IF(Q10=1,"Reduzir potencia luminaria","RETIRAR -"&TEXT(Q10-ROUNDUP((E10*IF(IFERROR(VLOOKUP(D10,NBR!$C:$F,4,0),J10)=J10,J10*1.2,IFERROR(VLOOKUP(D10,NBR!$C:$F,4,0),J10*1.2)))/(M10*N10*O10),0),"0")&" luminaria(s)"),"OK"))) -> #VALUE! | V10: =IF(E10*M10=0,"",ROUND((Q10*M10*N10*O10)/E10,0)) -> #VALUE! | W10: =IFERROR(VLOOKUP(D10,NBR!$C:$F,3,0),"") | X10: =IFERROR(VLOOKUP(D10,NBR!$C:$F,4,0),"") | Y10: =IFERROR(VLOOKUP(D10,NBR!$C:$F,2,0),"")
J11: =IFERROR(VLOOKUP(D11,NBR!$C:$E,3,0),"") | K11: =IF(E11*F11*I11=0,"",(4*E11)/((F11)*I11)) | M11: =IFERROR(VLOOKUP(L11,LAMPADAS!$A:$B,2,0),"") | P11: =IF(AND(E11<>"",J11<>"",M11<>"",N11<>"",O11<>"",N11<>0,O11<>0), ROUNDUP((E11*J11)/(M11*N11*O11),0), "") | R11: =IFERROR(VLOOKUP(L11,LAMPADAS!$A:$D,4,0),"") | S11: =IF(AND(Q11<>"",R11<>""),Q11*R11,"") | T11: =IF(E11*J11=0,"—",IF((Q11*M11*N11*O11)/E11<J11*0.9,"INSUFICIENTE -"&TEXT(ABS(((Q11*M11*N11*O11)/E11-J11)/J11)*100,"0")&"%",IF((Q11*M11*N11*O11)/E11>J11*1.31,"ACIMA +"&TEXT((((Q11*M11*N11*O11)/E11-J11)/J11)*100,"0")&"%","OK "&IF((Q11*M11*N11*O11)/E11>=J11,"+","")&TEXT((((Q11*M11*N11*O11)/E11-J11)/J11)*100,"0")&"%"))) -> #VALUE! | U11: =IF(E11*J11*M11=0,"",IF((Q11*M11*N11*O11)/E11<IF(IFERROR(VLOOKUP(D11,NBR!$C:$D,2,0),J11)=IFERROR(VLOOKUP(D11,NBR!$C:$F,4,0),J11),J11*0.9,IFERROR(VLOOKUP(D11,NBR!$C:$D,2,0),J11*0.9)),"COLOCAR +"&TEXT(ROUNDUP((E11*J11)/(M11*N11*O11),0)-Q11,"0")&" luminaria(s)",IF((Q11*M11*N11*O11)/E11>IF(IFERROR(VLOOKUP(D11,NBR!$C:$F,4,0),J11)=IFERROR(VLOOKUP(D11,NBR!$C:$D,2,0),J11),J11*1.2,IFERROR(VLOOKUP(D11,NBR!$C:$F,4,0),J11*1.2)),IF(Q11=1,"Reduzir potencia luminaria","RETIRAR -"&TEXT(Q11-ROUNDUP((E11*IF(IFERROR(VLOOKUP(D11,NBR!$C:$F,4,0),J11)=J11,J11*1.2,IFERROR(VLOOKUP(D11,NBR!$C:$F,4,0),J11*1.2)))/(M11*N11*O11),0),"0")&" luminaria(s)"),"OK"))) -> #VALUE! | V11: =IF(E11*M11=0,"",ROUND((Q11*M11*N11*O11)/E11,0)) -> #VALUE! | W11: =IFERROR(VLOOKUP(D11,NBR!$C:$F,3,0),"") | X11: =IFERROR(VLOOKUP(D11,NBR!$C:$F,4,0),"") | Y11: =IFERROR(VLOOKUP(D11,NBR!$C:$F,2,0),"")
J12: =IFERROR(VLOOKUP(D12,NBR!$C:$E,3,0),"") | K12: =IF(E12*F12*I12=0,"",(4*E12)/((F12)*I12)) | M12: =IFERROR(VLOOKUP(L12,LAMPADAS!$A:$B,2,0),"") | P12: =IF(AND(E12<>"",J12<>"",M12<>"",N12<>"",O12<>"",N12<>0,O12<>0), ROUNDUP((E12*J12)/(M12*N12*O12),0), "") | R12: =IFERROR(VLOOKUP(L12,LAMPADAS!$A:$D,4,0),"") | S12: =IF(AND(Q12<>"",R12<>""),Q12*R12,"") | T12: =IF(E12*J12=0,"—",IF((Q12*M12*N12*O12)/E12<J12*0.9,"INSUFICIENTE -"&TEXT(ABS(((Q12*M12*N12*O12)/E12-J12)/J12)*100,"0")&"%",IF((Q12*M12*N12*O12)/E12>J12*1.31,"ACIMA +"&TEXT((((Q12*M12*N12*O12)/E12-J12)/J12)*100,"0")&"%","OK "&IF((Q12*M12*N12*O12)/E12>=J12,"+","")&TEXT((((Q12*M12*N12*O12)/E12-J12)/J12)*100,"0")&"%"))) -> #VALUE! | U12: =IF(E12*J12*M12=0,"",IF((Q12*M12*N12*O12)/E12<IF(IFERROR(VLOOKUP(D12,NBR!$C:$D,2,0),J12)=IFERROR(VLOOKUP(D12,NBR!$C:$F,4,0),J12),J12*0.9,IFERROR(VLOOKUP(D12,NBR!$C:$D,2,0),J12*0.9)),"COLOCAR +"&TEXT(ROUNDUP((E12*J12)/(M12*N12*O12),0)-Q12,"0")&" luminaria(s)",IF((Q12*M12*N12*O12)/E12>IF(IFERROR(VLOOKUP(D12,NBR!$C:$F,4,0),J12)=IFERROR(VLOOKUP(D12,NBR!$C:$D,2,0),J12),J12*1.2,IFERROR(VLOOKUP(D12,NBR!$C:$F,4,0),J12*1.2)),IF(Q12=1,"Reduzir potencia luminaria","RETIRAR -"&TEXT(Q12-ROUNDUP((E12*IF(IFERROR(VLOOKUP(D12,NBR!$C:$F,4,0),J12)=J12,J12*1.2,IFERROR(VLOOKUP(D12,NBR!$C:$F,4,0),J12*1.2)))/(M12*N12*O12),0),"0")&" luminaria(s)"),"OK"))) -> #VALUE! | V12: =IF(E12*M12=0,"",ROUND((Q12*M12*N12*O12)/E12,0)) -> #VALUE! | W12: =IFERROR(VLOOKUP(D12,NBR!$C:$F,3,0),"") | X12: =IFERROR(VLOOKUP(D12,NBR!$C:$F,4,0),"") | Y12: =IFERROR(VLOOKUP(D12,NBR!$C:$F,2,0),"")
J13: =IFERROR(VLOOKUP(D13,NBR!$C:$E,3,0),"") | K13: =IF(E13*F13*I13=0,"",(4*E13)/((F13)*I13)) | M13: =IFERROR(VLOOKUP(L13,LAMPADAS!$A:$B,2,0),"") | P13: =IF(AND(E13<>"",J13<>"",M13<>"",N13<>"",O13<>"",N13<>0,O13<>0), ROUNDUP((E13*J13)/(M13*N13*O13),0), "") | R13: =IFERROR(VLOOKUP(L13,LAMPADAS!$A:$D,4,0),"") | S13: =IF(AND(Q13<>"",R13<>""),Q13*R13,"") | T13: =IF(E13*J13=0,"—",IF((Q13*M13*N13*O13)/E13<J13*0.9,"INSUFICIENTE -"&TEXT(ABS(((Q13*M13*N13*O13)/E13-J13)/J13)*100,"0")&"%",IF((Q13*M13*N13*O13)/E13>J13*1.31,"ACIMA +"&TEXT((((Q13*M13*N13*O13)/E13-J13)/J13)*100,"0")&"%","OK "&IF((Q13*M13*N13*O13)/E13>=J13,"+","")&TEXT((((Q13*M13*N13*O13)/E13-J13)/J13)*100,"0")&"%"))) -> #VALUE! | U13: =IF(E13*J13*M13=0,"",IF((Q13*M13*N13*O13)/E13<IF(IFERROR(VLOOKUP(D13,NBR!$C:$D,2,0),J13)=IFERROR(VLOOKUP(D13,NBR!$C:$F,4,0),J13),J13*0.9,IFERROR(VLOOKUP(D13,NBR!$C:$D,2,0),J13*0.9)),"COLOCAR +"&TEXT(ROUNDUP((E13*J13)/(M13*N13*O13),0)-Q13,"0")&" luminaria(s)",IF((Q13*M13*N13*O13)/E13>IF(IFERROR(VLOOKUP(D13,NBR!$C:$F,4,0),J13)=IFERROR(VLOOKUP(D13,NBR!$C:$D,2,0),J13),J13*1.2,IFERROR(VLOOKUP(D13,NBR!$C:$F,4,0),J13*1.2)),IF(Q13=1,"Reduzir potencia luminaria","RETIRAR -"&TEXT(Q13-ROUNDUP((E13*IF(IFERROR(VLOOKUP(D13,NBR!$C:$F,4,0),J13)=J13,J13*1.2,IFERROR(VLOOKUP(D13,NBR!$C:$F,4,0),J13*1.2)))/(M13*N13*O13),0),"0")&" luminaria(s)"),"OK"))) -> #VALUE! | V13: =IF(E13*M13=0,"",ROUND((Q13*M13*N13*O13)/E13,0)) -> #VALUE! | W13: =IFERROR(VLOOKUP(D13,NBR!$C:$F,3,0),"") | X13: =IFERROR(VLOOKUP(D13,NBR!$C:$F,4,0),"") | Y13: =IFERROR(VLOOKUP(D13,NBR!$C:$F,2,0),"")
J14: =IFERROR(VLOOKUP(D14,NBR!$C:$E,3,0),"") | K14: =IF(E14*F14*I14=0,"",(4*E14)/((F14)*I14)) | M14: =IFERROR(VLOOKUP(L14,LAMPADAS!$A:$B,2,0),"") | P14: =IF(AND(E14<>"",J14<>"",M14<>"",N14<>"",O14<>"",N14<>0,O14<>0), ROUNDUP((E14*J14)/(M14*N14*O14),0), "") | R14: =IFERROR(VLOOKUP(L14,LAMPADAS!$A:$D,4,0),"") | S14: =IF(AND(Q14<>"",R14<>""),Q14*R14,"") | T14: =IF(E14*J14=0,"—",IF((Q14*M14*N14*O14)/E14<J14*0.9,"INSUFICIENTE -"&TEXT(ABS(((Q14*M14*N14*O14)/E14-J14)/J14)*100,"0")&"%",IF((Q14*M14*N14*O14)/E14>J14*1.31,"ACIMA +"&TEXT((((Q14*M14*N14*O14)/E14-J14)/J14)*100,"0")&"%","OK "&IF((Q14*M14*N14*O14)/E14>=J14,"+","")&TEXT((((Q14*M14*N14*O14)/E14-J14)/J14)*100,"0")&"%"))) -> #VALUE! | U14: =IF(E14*J14*M14=0,"",IF((Q14*M14*N14*O14)/E14<IF(IFERROR(VLOOKUP(D14,NBR!$C:$D,2,0),J14)=IFERROR(VLOOKUP(D14,NBR!$C:$F,4,0),J14),J14*0.9,IFERROR(VLOOKUP(D14,NBR!$C:$D,2,0),J14*0.9)),"COLOCAR +"&TEXT(ROUNDUP((E14*J14)/(M14*N14*O14),0)-Q14,"0")&" luminaria(s)",IF((Q14*M14*N14*O14)/E14>IF(IFERROR(VLOOKUP(D14,NBR!$C:$F,4,0),J14)=IFERROR(VLOOKUP(D14,NBR!$C:$D,2,0),J14),J14*1.2,IFERROR(VLOOKUP(D14,NBR!$C:$F,4,0),J14*1.2)),IF(Q14=1,"Reduzir potencia luminaria","RETIRAR -"&TEXT(Q14-ROUNDUP((E14*IF(IFERROR(VLOOKUP(D14,NBR!$C:$F,4,0),J14)=J14,J14*1.2,IFERROR(VLOOKUP(D14,NBR!$C:$F,4,0),J14*1.2)))/(M14*N14*O14),0),"0")&" luminaria(s)"),"OK"))) -> #VALUE! | V14: =IF(E14*M14=0,"",ROUND((Q14*M14*N14*O14)/E14,0)) -> #VALUE! | W14: =IFERROR(VLOOKUP(D14,NBR!$C:$F,3,0),"") | X14: =IFERROR(VLOOKUP(D14,NBR!$C:$F,4,0),"") | Y14: =IFERROR(VLOOKUP(D14,NBR!$C:$F,2,0),"")
J15: =IFERROR(VLOOKUP(D15,NBR!$C:$E,3,0),"") | K15: =IF(E15*F15*I15=0,"",(4*E15)/((F15)*I15)) | M15: =IFERROR(VLOOKUP(L15,LAMPADAS!$A:$B,2,0),"") | P15: =IF(AND(E15<>"",J15<>"",M15<>"",N15<>"",O15<>"",N15<>0,O15<>0), ROUNDUP((E15*J15)/(M15*N15*O15),0), "") | R15: =IFERROR(VLOOKUP(L15,LAMPADAS!$A:$D,4,0),"") | S15: =IF(AND(Q15<>"",R15<>""),Q15*R15,"") | T15: =IF(E15*J15=0,"—",IF((Q15*M15*N15*O15)/E15<J15*0.9,"INSUFICIENTE -"&TEXT(ABS(((Q15*M15*N15*O15)/E15-J15)/J15)*100,"0")&"%",IF((Q15*M15*N15*O15)/E15>J15*1.31,"ACIMA +"&TEXT((((Q15*M15*N15*O15)/E15-J15)/J15)*100,"0")&"%","OK "&IF((Q15*M15*N15*O15)/E15>=J15,"+","")&TEXT((((Q15*M15*N15*O15)/E15-J15)/J15)*100,"0")&"%"))) -> #VALUE! | U15: =IF(E15*J15*M15=0,"",IF((Q15*M15*N15*O15)/E15<IF(IFERROR(VLOOKUP(D15,NBR!$C:$D,2,0),J15)=IFERROR(VLOOKUP(D15,NBR!$C:$F,4,0),J15),J15*0.9,IFERROR(VLOOKUP(D15,NBR!$C:$D,2,0),J15*0.9)),"COLOCAR +"&TEXT(ROUNDUP((E15*J15)/(M15*N15*O15),0)-Q15,"0")&" luminaria(s)",IF((Q15*M15*N15*O15)/E15>IF(IFERROR(VLOOKUP(D15,NBR!$C:$F,4,0),J15)=IFERROR(VLOOKUP(D15,NBR!$C:$D,2,0),J15),J15*1.2,IFERROR(VLOOKUP(D15,NBR!$C:$F,4,0),J15*1.2)),IF(Q15=1,"Reduzir potencia luminaria","RETIRAR -"&TEXT(Q15-ROUNDUP((E15*IF(IFERROR(VLOOKUP(D15,NBR!$C:$F,4,0),J15)=J15,J15*1.2,IFERROR(VLOOKUP(D15,NBR!$C:$F,4,0),J15*1.2)))/(M15*N15*O15),0),"0")&" luminaria(s)"),"OK"))) -> #VALUE! | V15: =IF(E15*M15=0,"",ROUND((Q15*M15*N15*O15)/E15,0)) -> #VALUE! | W15: =IFERROR(VLOOKUP(D15,NBR!$C:$F,3,0),"") | X15: =IFERROR(VLOOKUP(D15,NBR!$C:$F,4,0),"") | Y15: =IFERROR(VLOOKUP(D15,NBR!$C:$F,2,0),"")
J16: =IFERROR(VLOOKUP(D16,NBR!$C:$E,3,0),"") | K16: =IF(E16*F16*I16=0,"",(4*E16)/((F16)*I16)) | M16: =IFERROR(VLOOKUP(L16,LAMPADAS!$A:$B,2,0),"") | P16: =IF(AND(E16<>"",J16<>"",M16<>"",N16<>"",O16<>"",N16<>0,O16<>0), ROUNDUP((E16*J16)/(M16*N16*O16),0), "") | R16: =IFERROR(VLOOKUP(L16,LAMPADAS!$A:$D,4,0),"") | S16: =IF(AND(Q16<>"",R16<>""),Q16*R16,"") | T16: =IF(E16*J16=0,"—",IF((Q16*M16*N16*O16)/E16<J16*0.9,"INSUFICIENTE -"&TEXT(ABS(((Q16*M16*N16*O16)/E16-J16)/J16)*100,"0")&"%",IF((Q16*M16*N16*O16)/E16>J16*1.31,"ACIMA +"&TEXT((((Q16*M16*N16*O16)/E16-J16)/J16)*100,"0")&"%","OK "&IF((Q16*M16*N16*O16)/E16>=J16,"+","")&TEXT((((Q16*M16*N16*O16)/E16-J16)/J16)*100,"0")&"%"))) -> #VALUE! | U16: =IF(E16*J16*M16=0,"",IF((Q16*M16*N16*O16)/E16<IF(IFERROR(VLOOKUP(D16,NBR!$C:$D,2,0),J16)=IFERROR(VLOOKUP(D16,NBR!$C:$F,4,0),J16),J16*0.9,IFERROR(VLOOKUP(D16,NBR!$C:$D,2,0),J16*0.9)),"COLOCAR +"&TEXT(ROUNDUP((E16*J16)/(M16*N16*O16),0)-Q16,"0")&" luminaria(s)",IF((Q16*M16*N16*O16)/E16>IF(IFERROR(VLOOKUP(D16,NBR!$C:$F,4,0),J16)=IFERROR(VLOOKUP(D16,NBR!$C:$D,2,0),J16),J16*1.2,IFERROR(VLOOKUP(D16,NBR!$C:$F,4,0),J16*1.2)),IF(Q16=1,"Reduzir potencia luminaria","RETIRAR -"&TEXT(Q16-ROUNDUP((E16*IF(IFERROR(VLOOKUP(D16,NBR!$C:$F,4,0),J16)=J16,J16*1.2,IFERROR(VLOOKUP(D16,NBR!$C:$F,4,0),J16*1.2)))/(M16*N16*O16),0),"0")&" luminaria(s)"),"OK"))) -> #VALUE! | V16: =IF(E16*M16=0,"",ROUND((Q16*M16*N16*O16)/E16,0)) -> #VALUE! | W16: =IFERROR(VLOOKUP(D16,NBR!$C:$F,3,0),"") | X16: =IFERROR(VLOOKUP(D16,NBR!$C:$F,4,0),"") | Y16: =IFERROR(VLOOKUP(D16,NBR!$C:$F,2,0),"")
J17: =IFERROR(VLOOKUP(D17,NBR!$C:$E,3,0),"") | K17: =IF(E17*F17*I17=0,"",(4*E17)/((F17)*I17)) | M17: =IFERROR(VLOOKUP(L17,LAMPADAS!$A:$B,2,0),"") | P17: =IF(AND(E17<>"",J17<>"",M17<>"",N17<>"",O17<>"",N17<>0,O17<>0), ROUNDUP((E17*J17)/(M17*N17*O17),0), "") | R17: =IFERROR(VLOOKUP(L17,LAMPADAS!$A:$D,4,0),"") | S17: =IF(AND(Q17<>"",R17<>""),Q17*R17,"") | T17: =IF(E17*J17=0,"—",IF((Q17*M17*N17*O17)/E17<J17*0.9,"INSUFICIENTE -"&TEXT(ABS(((Q17*M17*N17*O17)/E17-J17)/J17)*100,"0")&"%",IF((Q17*M17*N17*O17)/E17>J17*1.31,"ACIMA +"&TEXT((((Q17*M17*N17*O17)/E17-J17)/J17)*100,"0")&"%","OK "&IF((Q17*M17*N17*O17)/E17>=J17,"+","")&TEXT((((Q17*M17*N17*O17)/E17-J17)/J17)*100,"0")&"%"))) -> #VALUE! | U17: =IF(E17*J17*M17=0,"",IF((Q17*M17*N17*O17)/E17<IF(IFERROR(VLOOKUP(D17,NBR!$C:$D,2,0),J17)=IFERROR(VLOOKUP(D17,NBR!$C:$F,4,0),J17),J17*0.9,IFERROR(VLOOKUP(D17,NBR!$C:$D,2,0),J17*0.9)),"COLOCAR +"&TEXT(ROUNDUP((E17*J17)/(M17*N17*O17),0)-Q17,"0")&" luminaria(s)",IF((Q17*M17*N17*O17)/E17>IF(IFERROR(VLOOKUP(D17,NBR!$C:$F,4,0),J17)=IFERROR(VLOOKUP(D17,NBR!$C:$D,2,0),J17),J17*1.2,IFERROR(VLOOKUP(D17,NBR!$C:$F,4,0),J17*1.2)),IF(Q17=1,"Reduzir potencia luminaria","RETIRAR -"&TEXT(Q17-ROUNDUP((E17*IF(IFERROR(VLOOKUP(D17,NBR!$C:$F,4,0),J17)=J17,J17*1.2,IFERROR(VLOOKUP(D17,NBR!$C:$F,4,0),J17*1.2)))/(M17*N17*O17),0),"0")&" luminaria(s)"),"OK"))) -> #VALUE! | V17: =IF(E17*M17=0,"",ROUND((Q17*M17*N17*O17)/E17,0)) -> #VALUE! | W17: =IFERROR(VLOOKUP(D17,NBR!$C:$F,3,0),"") | X17: =IFERROR(VLOOKUP(D17,NBR!$C:$F,4,0),"") | Y17: =IFERROR(VLOOKUP(D17,NBR!$C:$F,2,0),"")
... J22: =IFERROR(VLOOKUP(D22,NBR!$C:$E,3,0),"") | K22: =IF(E22*F22*I22=0,"",(4*E22)/((F22)*I22)) | M22: =IFERROR(VLOOKUP(L22,LAMPADAS!$A:$B,2,0),"") | P22: =IF(AND(E22<>"",J22<>"",M22<>"",N22<>"",O22<>"",N22<>0,O22<>0), ROUNDUP((E22*J22)/(M22*N22*O22),0), "") | R22: =IFERROR(VLOOKUP(L22,LAMPADAS!$A:$D,4,0),"") | S22: =IF(AND(Q22<>"",R22<>""),Q22*R22,"") | T22: =IF(E22*J22=0,"—",IF((Q22*M22*N22*O22)/E22<J22*0.9,"INSUFICIENTE -"&TEXT(ABS(((Q22*M22*N22*O22)/E22-J22)/J22)*100,"0")&"%",IF((Q22*M22*N22*O22)/E22>J22*1.31,"ACIMA +"&TEXT((((Q22*M22*N22*O22)/E22-J22)/J22)*100,"0")&"%","OK "&IF((Q22*M22*N22*O22)/E22>=J22,"+","")&TEXT((((Q22*M22*N22*O22)/E22-J22)/J22)*100,"0")&"%"))) -> #VALUE! | U22: =IF(E22*J22*M22=0,"",IF((Q22*M22*N22*O22)/E22<IF(IFERROR(VLOOKUP(D22,NBR!$C:$D,2,0),J22)=IFERROR(VLOOKUP(D22,NBR!$C:$F,4,0),J22),J22*0.9,IFERROR(VLOOKUP(D22,NBR!$C:$D,2,0),J22*0.9)),"COLOCAR +"&TEXT(ROUNDUP((E22*J22)/(M22*N22*O22),0)-Q22,"0")&" luminaria(s)",IF((Q22*M22*N22*O22)/E22>IF(IFERROR(VLOOKUP(D22,NBR!$C:$F,4,0),J22)=IFERROR(VLOOKUP(D22,NBR!$C:$D,2,0),J22),J22*1.2,IFERROR(VLOOKUP(D22,NBR!$C:$F,4,0),J22*1.2)),IF(Q22=1,"Reduzir potencia luminaria","RETIRAR -"&TEXT(Q22-ROUNDUP((E22*IF(IFERROR(VLOOKUP(D22,NBR!$C:$F,4,0),J22)=J22,J22*1.2,IFERROR(VLOOKUP(D22,NBR!$C:$F,4,0),J22*1.2)))/(M22*N22*O22),0),"0")&" luminaria(s)"),"OK"))) -> #VALUE! | V22: =IF(E22*M22=0,"",ROUND((Q22*M22*N22*O22)/E22,0)) -> #VALUE! | W22: =IFERROR(VLOOKUP(D22,NBR!$C:$F,3,0),"") | X22: =IFERROR(VLOOKUP(D22,NBR!$C:$F,4,0),"") | Y22: =IFERROR(VLOOKUP(D22,NBR!$C:$F,2,0),"")
J23: =IFERROR(VLOOKUP(D23,NBR!$C:$E,3,0),"") | K23: =IF(E23*F23*I23=0,"",(4*E23)/((F23)*I23)) | M23: =IFERROR(VLOOKUP(L23,LAMPADAS!$A:$B,2,0),"") | P23: =IF(AND(E23<>"",J23<>"",M23<>"",N23<>"",O23<>"",N23<>0,O23<>0), ROUNDUP((E23*J23)/(M23*N23*O23),0), "") | R23: =IFERROR(VLOOKUP(L23,LAMPADAS!$A:$D,4,0),"") | S23: =IF(AND(Q23<>"",R23<>""),Q23*R23,"") | T23: =IF(E23*J23=0,"—",IF((Q23*M23*N23*O23)/E23<J23*0.9,"INSUFICIENTE -"&TEXT(ABS(((Q23*M23*N23*O23)/E23-J23)/J23)*100,"0")&"%",IF((Q23*M23*N23*O23)/E23>J23*1.31,"ACIMA +"&TEXT((((Q23*M23*N23*O23)/E23-J23)/J23)*100,"0")&"%","OK "&IF((Q23*M23*N23*O23)/E23>=J23,"+","")&TEXT((((Q23*M23*N23*O23)/E23-J23)/J23)*100,"0")&"%"))) -> #VALUE! | U23: =IF(E23*J23*M23=0,"",IF((Q23*M23*N23*O23)/E23<IF(IFERROR(VLOOKUP(D23,NBR!$C:$D,2,0),J23)=IFERROR(VLOOKUP(D23,NBR!$C:$F,4,0),J23),J23*0.9,IFERROR(VLOOKUP(D23,NBR!$C:$D,2,0),J23*0.9)),"COLOCAR +"&TEXT(ROUNDUP((E23*J23)/(M23*N23*O23),0)-Q23,"0")&" luminaria(s)",IF((Q23*M23*N23*O23)/E23>IF(IFERROR(VLOOKUP(D23,NBR!$C:$F,4,0),J23)=IFERROR(VLOOKUP(D23,NBR!$C:$D,2,0),J23),J23*1.2,IFERROR(VLOOKUP(D23,NBR!$C:$F,4,0),J23*1.2)),IF(Q23=1,"Reduzir potencia luminaria","RETIRAR -"&TEXT(Q23-ROUNDUP((E23*IF(IFERROR(VLOOKUP(D23,NBR!$C:$F,4,0),J23)=J23,J23*1.2,IFERROR(VLOOKUP(D23,NBR!$C:$F,4,0),J23*1.2)))/(M23*N23*O23),0),"0")&" luminaria(s)"),"OK"))) -> #VALUE! | V23: =IF(E23*M23=0,"",ROUND((Q23*M23*N23*O23)/E23,0)) -> #VALUE! | W23: =IFERROR(VLOOKUP(D23,NBR!$C:$F,3,0),"") | X23: =IFERROR(VLOOKUP(D23,NBR!$C:$F,3,0),"") | Y23: =IFERROR(VLOOKUP(D23,NBR!$C:$F,2,0),"")
J24: =IFERROR(VLOOKUP(D24,NBR!$C:$E,3,0),"") | K24: =IF(E24*F24*I24=0,"",(4*E24)/((F24)*I24)) | M24: =IFERROR(VLOOKUP(L24,LAMPADAS!$A:$B,2,0),"") | P24: =IF(AND(E24<>"",J24<>"",M24<>"",N24<>"",O24<>"",N24<>0,O24<>0), ROUNDUP((E24*J24)/(M24*N24*O24),0), "") | R24: =IFERROR(VLOOKUP(L24,LAMPADAS!$A:$D,4,0),"") | S24: =IF(AND(Q24<>"",R24<>""),Q24*R24,"") | T24: =IF(E24*J24=0,"—",IF((Q24*M24*N24*O24)/E24<J24*0.9,"INSUFICIENTE -"&TEXT(ABS(((Q24*M24*N24*O24)/E24-J24)/J24)*100,"0")&"%",IF((Q24*M24*N24*O24)/E24>J24*1.31,"ACIMA +"&TEXT((((Q24*M24*N24*O24)/E24-J24)/J24)*100,"0")&"%","OK "&IF((Q24*M24*N24*O24)/E24>=J24,"+","")&TEXT((((Q24*M24*N24*O24)/E24-J24)/J24)*100,"0")&"%"))) -> #VALUE! | U24: =IF(E24*J24*M24=0,"",IF((Q24*M24*N24*O24)/E24<IF(IFERROR(VLOOKUP(D24,NBR!$C:$D,2,0),J24)=IFERROR(VLOOKUP(D24,NBR!$C:$F,4,0),J24),J24*0.9,IFERROR(VLOOKUP(D24,NBR!$C:$D,2,0),J24*0.9)),"COLOCAR +"&TEXT(ROUNDUP((E24*J24)/(M24*N24*O24),0)-Q24,"0")&" luminaria(s)",IF((Q24*M24*N24*O24)/E24>IF(IFERROR(VLOOKUP(D24,NBR!$C:$F,4,0),J24)=IFERROR(VLOOKUP(D24,NBR!$C:$D,2,0),J24),J24*1.2,IFERROR(VLOOKUP(D24,NBR!$C:$F,4,0),J24*1.2)),IF(Q24=1,"Reduzir potencia luminaria","RETIRAR -"&TEXT(Q24-ROUNDUP((E24*IF(IFERROR(VLOOKUP(D24,NBR!$C:$F,4,0),J24)=J24,J24*1.2,IFERROR(VLOOKUP(D24,NBR!$C:$F,4,0),J24*1.2)))/(M24*N24*O24),0),"0")&" luminaria(s)"),"OK"))) -> #VALUE! | V24: =IF(E24*M24=0,"",ROUND((Q24*M24*N24*O24)/E24,0)) -> #VALUE! | W24: =IFERROR(VLOOKUP(D24,NBR!$C:$F,3,0),"") | X24: =IFERROR(VLOOKUP(D24,NBR!$C:$F,3,0),"") | Y24: =IFERROR(VLOOKUP(D24,NBR!$C:$F,2,0),"")
J25: =IFERROR(VLOOKUP(D25,NBR!$C:$E,3,0),"") | K25: =IF(E25*F25*I25=0,"",(4*E25)/((F25)*I25)) | M25: =IFERROR(VLOOKUP(L25,LAMPADAS!$A:$B,2,0),"") | P25: =IF(AND(E25<>"",J25<>"",M25<>"",N25<>"",O25<>"",N25<>0,O25<>0), ROUNDUP((E25*J25)/(M25*N25*O25),0), "") | R25: =IFERROR(VLOOKUP(L25,LAMPADAS!$A:$D,4,0),"") | S25: =IF(AND(Q25<>"",R25<>""),Q25*R25,"") | T25: =IF(E25*J25=0,"—",IF((Q25*M25*N25*O25)/E25<J25*0.9,"INSUFICIENTE -"&TEXT(ABS(((Q25*M25*N25*O25)/E25-J25)/J25)*100,"0")&"%",IF((Q25*M25*N25*O25)/E25>J25*1.31,"ACIMA +"&TEXT((((Q25*M25*N25*O25)/E25-J25)/J25)*100,"0")&"%","OK "&IF((Q25*M25*N25*O25)/E25>=J25,"+","")&TEXT((((Q25*M25*N25*O25)/E25-J25)/J25)*100,"0")&"%"))) -> #VALUE! | U25: =IF(E25*J25*M25=0,"",IF((Q25*M25*N25*O25)/E25<IF(IFERROR(VLOOKUP(D25,NBR!$C:$D,2,0),J25)=IFERROR(VLOOKUP(D25,NBR!$C:$F,4,0),J25),J25*0.9,IFERROR(VLOOKUP(D25,NBR!$C:$D,2,0),J25*0.9)),"COLOCAR +"&TEXT(ROUNDUP((E25*J25)/(M25*N25*O25),0)-Q25,"0")&" luminaria(s)",IF((Q25*M25*N25*O25)/E25>IF(IFERROR(VLOOKUP(D25,NBR!$C:$F,4,0),J25)=IFERROR(VLOOKUP(D25,NBR!$C:$D,2,0),J25),J25*1.2,IFERROR(VLOOKUP(D25,NBR!$C:$F,4,0),J25*1.2)),IF(Q25=1,"Reduzir potencia luminaria","RETIRAR -"&TEXT(Q25-ROUNDUP((E25*IF(IFERROR(VLOOKUP(D25,NBR!$C:$F,4,0),J25)=J25,J25*1.2,IFERROR(VLOOKUP(D25,NBR!$C:$F,4,0),J25*1.2)))/(M25*N25*O25),0),"0")&" luminaria(s)"),"OK"))) -> #VALUE! | V25: =IF(E25*M25=0,"",ROUND((Q25*M25*N25*O25)/E25,0)) -> #VALUE! | W25: =IFERROR(VLOOKUP(D25,NBR!$C:$F,3,0),"") | X25: =IFERROR(VLOOKUP(D25,NBR!$C:$F,3,0),"") | Y25: =IFERROR(VLOOKUP(D25,NBR!$C:$F,2,0),"")
J26: =IFERROR(VLOOKUP(D26,NBR!$C:$E,3,0),"") | K26: =IF(E26*F26*I26=0,"",(4*E26)/((F26)*I26)) | M26: =IFERROR(VLOOKUP(L26,LAMPADAS!$A:$B,2,0),"") | P26: =IF(AND(E26<>"",J26<>"",M26<>"",N26<>"",O26<>"",N26<>0,O26<>0), ROUNDUP((E26*J26)/(M26*N26*O26),0), "") | R26: =IFERROR(VLOOKUP(L26,#REF!,4,0),"") | S26: =IF(AND(Q26<>"",R26<>""),Q26*R26,"") | T26: =IF(E26*J26=0,"—",IF((Q26*M26*N26*O26)/E26<J26*0.9,"INSUFICIENTE -"&TEXT(ABS(((Q26*M26*N26*O26)/E26-J26)/J26)*100,"0")&"%",IF((Q26*M26*N26*O26)/E26>J26*1.31,"ACIMA +"&TEXT((((Q26*M26*N26*O26)/E26-J26)/J26)*100,"0")&"%","OK "&IF((Q26*M26*N26*O26)/E26>=J26,"+","")&TEXT((((Q26*M26*N26*O26)/E26-J26)/J26)*100,"0")&"%"))) -> #VALUE! | U26: =IF(E26*J26*M26=0,"",IF((Q26*M26*N26*O26)/E26<IF(IFERROR(VLOOKUP(D26,NBR!$C:$D,2,0),J26)=IFERROR(VLOOKUP(D26,NBR!$C:$F,4,0),J26),J26*0.9,IFERROR(VLOOKUP(D26,NBR!$C:$D,2,0),J26*0.9)),"COLOCAR +"&TEXT(ROUNDUP((E26*J26)/(M26*N26*O26),0)-Q26,"0")&" luminaria(s)",IF((Q26*M26*N26*O26)/E26>IF(IFERROR(VLOOKUP(D26,NBR!$C:$F,4,0),J26)=IFERROR(VLOOKUP(D26,NBR!$C:$D,2,0),J26),J26*1.2,IFERROR(VLOOKUP(D26,NBR!$C:$F,4,0),J26*1.2)),IF(Q26=1,"Reduzir potencia luminaria","RETIRAR -"&TEXT(Q26-ROUNDUP((E26*IF(IFERROR(VLOOKUP(D26,NBR!$C:$F,4,0),J26)=J26,J26*1.2,IFERROR(VLOOKUP(D26,NBR!$C:$F,4,0),J26*1.2)))/(M26*N26*O26),0),"0")&" luminaria(s)"),"OK"))) -> #VALUE! | V26: =IF(E26*M26=0,"",ROUND((Q26*M26*N26*O26)/E26,0)) -> #VALUE!
J27: =IFERROR(VLOOKUP(D27,NBR!$C:$E,3,0),"") | K27: =IF(E27*F27*I27=0,"",(4*E27)/((F27)*I27)) | M27: =IFERROR(VLOOKUP(L27,LAMPADAS!$A:$B,2,0),"") | P27: =IF(AND(E27<>"",J27<>"",M27<>"",N27<>"",O27<>"",N27<>0,O27<>0), ROUNDUP((E27*J27)/(M27*N27*O27),0), "") | R27: =IFERROR(VLOOKUP(L27,#REF!,4,0),"") | S27: =IF(AND(Q27<>"",R27<>""),Q27*R27,"") | T27: =IF(E27*J27=0,"—",IF((Q27*M27*N27*O27)/E27<J27*0.9,"INSUFICIENTE -"&TEXT(ABS(((Q27*M27*N27*O27)/E27-J27)/J27)*100,"0")&"%",IF((Q27*M27*N27*O27)/E27>J27*1.31,"ACIMA +"&TEXT((((Q27*M27*N27*O27)/E27-J27)/J27)*100,"0")&"%","OK "&IF((Q27*M27*N27*O27)/E27>=J27,"+","")&TEXT((((Q27*M27*N27*O27)/E27-J27)/J27)*100,"0")&"%"))) -> #VALUE! | U27: =IF(E27*J27*M27=0,"",IF((Q27*M27*N27*O27)/E27<IF(IFERROR(VLOOKUP(D27,NBR!$C:$D,2,0),J27)=IFERROR(VLOOKUP(D27,NBR!$C:$F,4,0),J27),J27*0.9,IFERROR(VLOOKUP(D27,NBR!$C:$D,2,0),J27*0.9)),"COLOCAR +"&TEXT(ROUNDUP((E27*J27)/(M27*N27*O27),0)-Q27,"0")&" luminaria(s)",IF((Q27*M27*N27*O27)/E27>IF(IFERROR(VLOOKUP(D27,NBR!$C:$F,4,0),J27)=IFERROR(VLOOKUP(D27,NBR!$C:$D,2,0),J27),J27*1.2,IFERROR(VLOOKUP(D27,NBR!$C:$F,4,0),J27*1.2)),IF(Q27=1,"Reduzir potencia luminaria","RETIRAR -"&TEXT(Q27-ROUNDUP((E27*IF(IFERROR(VLOOKUP(D27,NBR!$C:$F,4,0),J27)=J27,J27*1.2,IFERROR(VLOOKUP(D27,NBR!$C:$F,4,0),J27*1.2)))/(M27*N27*O27),0),"0")&" luminaria(s)"),"OK"))) -> #VALUE! | V27: =IF(E27*M27=0,"",ROUND((Q27*M27*N27*O27)/E27,0)) -> #VALUE!
J28: =IFERROR(VLOOKUP(D28,NBR!$C:$E,3,0),"") | K28: =IF(E28*F28*I28=0,"",(4*E28)/((F28)*I28)) | M28: =IFERROR(VLOOKUP(L28,LAMPADAS!$A:$B,2,0),"") | P28: =IF(AND(E28<>"",J28<>"",M28<>"",N28<>"",O28<>"",N28<>0,O28<>0), ROUNDUP((E28*J28)/(M28*N28*O28),0), "") | R28: =IFERROR(VLOOKUP(L28,#REF!,4,0),"") | S28: =IF(AND(Q28<>"",R28<>""),Q28*R28,"") | T28: =IF(E28*J28=0,"—",IF((Q28*M28*N28*O28)/E28<J28*0.9,"INSUFICIENTE -"&TEXT(ABS(((Q28*M28*N28*O28)/E28-J28)/J28)*100,"0")&"%",IF((Q28*M28*N28*O28)/E28>J28*1.31,"ACIMA +"&TEXT((((Q28*M28*N28*O28)/E28-J28)/J28)*100,"0")&"%","OK "&IF((Q28*M28*N28*O28)/E28>=J28,"+","")&TEXT((((Q28*M28*N28*O28)/E28-J28)/J28)*100,"0")&"%"))) -> #VALUE! | U28: =IF(E28*J28*M28=0,"",IF((Q28*M28*N28*O28)/E28<IF(IFERROR(VLOOKUP(D28,NBR!$C:$D,2,0),J28)=IFERROR(VLOOKUP(D28,NBR!$C:$F,4,0),J28),J28*0.9,IFERROR(VLOOKUP(D28,NBR!$C:$D,2,0),J28*0.9)),"COLOCAR +"&TEXT(ROUNDUP((E28*J28)/(M28*N28*O28),0)-Q28,"0")&" luminaria(s)",IF((Q28*M28*N28*O28)/E28>IF(IFERROR(VLOOKUP(D28,NBR!$C:$F,4,0),J28)=IFERROR(VLOOKUP(D28,NBR!$C:$D,2,0),J28),J28*1.2,IFERROR(VLOOKUP(D28,NBR!$C:$F,4,0),J28*1.2)),IF(Q28=1,"Reduzir potencia luminaria","RETIRAR -"&TEXT(Q28-ROUNDUP((E28*IF(IFERROR(VLOOKUP(D28,NBR!$C:$F,4,0),J28)=J28,J28*1.2,IFERROR(VLOOKUP(D28,NBR!$C:$F,4,0),J28*1.2)))/(M28*N28*O28),0),"0")&" luminaria(s)"),"OK"))) -> #VALUE! | V28: =IF(E28*M28=0,"",ROUND((Q28*M28*N28*O28)/E28,0)) -> #VALUE!
J29: =IFERROR(VLOOKUP(D29,NBR!$C:$E,3,0),"") | K29: =IF(E29*F29*I29=0,"",(4*E29)/((F29)*I29)) | M29: =IFERROR(VLOOKUP(L29,LAMPADAS!$A:$B,2,0),"") | P29: =IF(AND(E29<>"",J29<>"",M29<>"",N29<>"",O29<>"",N29<>0,O29<>0), ROUNDUP((E29*J29)/(M29*N29*O29),0), "") | R29: =IFERROR(VLOOKUP(L29,#REF!,4,0),"") | S29: =IF(AND(Q29<>"",R29<>""),Q29*R29,"") | T29: =IF(E29*J29=0,"—",IF((Q29*M29*N29*O29)/E29<J29*0.9,"INSUFICIENTE -"&TEXT(ABS(((Q29*M29*N29*O29)/E29-J29)/J29)*100,"0")&"%",IF((Q29*M29*N29*O29)/E29>J29*1.31,"ACIMA +"&TEXT((((Q29*M29*N29*O29)/E29-J29)/J29)*100,"0")&"%","OK "&IF((Q29*M29*N29*O29)/E29>=J29,"+","")&TEXT((((Q29*M29*N29*O29)/E29-J29)/J29)*100,"0")&"%"))) -> #VALUE! | U29: =IF(E29*J29*M29=0,"",IF((Q29*M29*N29*O29)/E29<IF(IFERROR(VLOOKUP(D29,NBR!$C:$D,2,0),J29)=IFERROR(VLOOKUP(D29,NBR!$C:$F,4,0),J29),J29*0.9,IFERROR(VLOOKUP(D29,NBR!$C:$D,2,0),J29*0.9)),"COLOCAR +"&TEXT(ROUNDUP((E29*J29)/(M29*N29*O29),0)-Q29,"0")&" luminaria(s)",IF((Q29*M29*N29*O29)/E29>IF(IFERROR(VLOOKUP(D29,NBR!$C:$F,4,0),J29)=IFERROR(VLOOKUP(D29,NBR!$C:$D,2,0),J29),J29*1.2,IFERROR(VLOOKUP(D29,NBR!$C:$F,4,0),J29*1.2)),IF(Q29=1,"Reduzir potencia luminaria","RETIRAR -"&TEXT(Q29-ROUNDUP((E29*IF(IFERROR(VLOOKUP(D29,NBR!$C:$F,4,0),J29)=J29,J29*1.2,IFERROR(VLOOKUP(D29,NBR!$C:$F,4,0),J29*1.2)))/(M29*N29*O29),0),"0")&" luminaria(s)"),"OK"))) -> #VALUE! | V29: =IF(E29*M29=0,"",ROUND((Q29*M29*N29*O29)/E29,0)) -> #VALUE!
J30: =IFERROR(VLOOKUP(D30,NBR!$C:$E,3,0),"") | K30: =IF(E30*F30*I30=0,"",(4*E30)/((F30)*I30)) | M30: =IFERROR(VLOOKUP(L30,LAMPADAS!$A:$B,2,0),"") | P30: =IF(AND(E30<>"",J30<>"",M30<>"",N30<>"",O30<>"",N30<>0,O30<>0), ROUNDUP((E30*J30)/(M30*N30*O30),0), "") | R30: =IFERROR(VLOOKUP(L30,#REF!,4,0),"") | S30: =IF(AND(Q30<>"",R30<>""),Q30*R30,"") | T30: =IF(E30*J30=0,"—",IF((Q30*M30*N30*O30)/E30<J30*0.9,"INSUFICIENTE -"&TEXT(ABS(((Q30*M30*N30*O30)/E30-J30)/J30)*100,"0")&"%",IF((Q30*M30*N30*O30)/E30>J30*1.31,"ACIMA +"&TEXT((((Q30*M30*N30*O30)/E30-J30)/J30)*100,"0")&"%","OK "&IF((Q30*M30*N30*O30)/E30>=J30,"+","")&TEXT((((Q30*M30*N30*O30)/E30-J30)/J30)*100,"0")&"%"))) -> #VALUE! | U30: =IF(E30*J30*M30=0,"",IF((Q30*M30*N30*O30)/E30<IF(IFERROR(VLOOKUP(D30,NBR!$C:$D,2,0),J30)=IFERROR(VLOOKUP(D30,NBR!$C:$F,4,0),J30),J30*0.9,IFERROR(VLOOKUP(D30,NBR!$C:$D,2,0),J30*0.9)),"COLOCAR +"&TEXT(ROUNDUP((E30*J30)/(M30*N30*O30),0)-Q30,"0")&" luminaria(s)",IF((Q30*M30*N30*O30)/E30>IF(IFERROR(VLOOKUP(D30,NBR!$C:$F,4,0),J30)=IFERROR(VLOOKUP(D30,NBR!$C:$D,2,0),J30),J30*1.2,IFERROR(VLOOKUP(D30,NBR!$C:$F,4,0),J30*1.2)),IF(Q30=1,"Reduzir potencia luminaria","RETIRAR -"&TEXT(Q30-ROUNDUP((E30*IF(IFERROR(VLOOKUP(D30,NBR!$C:$F,4,0),J30)=J30,J30*1.2,IFERROR(VLOOKUP(D30,NBR!$C:$F,4,0),J30*1.2)))/(M30*N30*O30),0),"0")&" luminaria(s)"),"OK"))) -> #VALUE! | V30: =IF(E30*M30=0,"",ROUND((Q30*M30*N30*O30)/E30,0)) -> #VALUE!
J31: =IFERROR(VLOOKUP(D31,NBR!$C:$E,3,0),"") | K31: =IF(E31*F31*I31=0,"",(4*E31)/((F31)*I31)) | M31: =IFERROR(VLOOKUP(L31,LAMPADAS!$A:$B,2,0),"") | P31: =IF(AND(E31<>"",J31<>"",M31<>"",N31<>"",O31<>"",N31<>0,O31<>0), ROUNDUP((E31*J31)/(M31*N31*O31),0), "") | R31: =IFERROR(VLOOKUP(L31,#REF!,4,0),"") | S31: =IF(AND(Q31<>"",R31<>""),Q31*R31,"") | T31: =IF(E31*J31=0,"—",IF((Q31*M31*N31*O31)/E31<J31*0.9,"INSUFICIENTE -"&TEXT(ABS(((Q31*M31*N31*O31)/E31-J31)/J31)*100,"0")&"%",IF((Q31*M31*N31*O31)/E31>J31*1.31,"ACIMA +"&TEXT((((Q31*M31*N31*O31)/E31-J31)/J31)*100,"0")&"%","OK "&IF((Q31*M31*N31*O31)/E31>=J31,"+","")&TEXT((((Q31*M31*N31*O31)/E31-J31)/J31)*100,"0")&"%"))) -> #VALUE! | U31: =IF(E31*J31*M31=0,"",IF((Q31*M31*N31*O31)/E31<IF(IFERROR(VLOOKUP(D31,NBR!$C:$D,2,0),J31)=IFERROR(VLOOKUP(D31,NBR!$C:$F,4,0),J31),J31*0.9,IFERROR(VLOOKUP(D31,NBR!$C:$D,2,0),J31*0.9)),"COLOCAR +"&TEXT(ROUNDUP((E31*J31)/(M31*N31*O31),0)-Q31,"0")&" luminaria(s)",IF((Q31*M31*N31*O31)/E31>IF(IFERROR(VLOOKUP(D31,NBR!$C:$F,4,0),J31)=IFERROR(VLOOKUP(D31,NBR!$C:$D,2,0),J31),J31*1.2,IFERROR(VLOOKUP(D31,NBR!$C:$F,4,0),J31*1.2)),IF(Q31=1,"Reduzir potencia luminaria","RETIRAR -"&TEXT(Q31-ROUNDUP((E31*IF(IFERROR(VLOOKUP(D31,NBR!$C:$F,4,0),J31)=J31,J31*1.2,IFERROR(VLOOKUP(D31,NBR!$C:$F,4,0),J31*1.2)))/(M31*N31*O31),0),"0")&" luminaria(s)"),"OK"))) -> #VALUE! | V31: =IF(E31*M31=0,"",ROUND((Q31*M31*N31*O31)/E31,0)) -> #VALUE!
J32: =IFERROR(VLOOKUP(D32,NBR!$C:$E,3,0),"") | K32: =IF(E32*F32*I32=0,"",(4*E32)/((F32)*I32)) | M32: =IFERROR(VLOOKUP(L32,LAMPADAS!$A:$B,2,0),"") | P32: =IF(AND(E32<>"",J32<>"",M32<>"",N32<>"",O32<>"",N32<>0,O32<>0), ROUNDUP((E32*J32)/(M32*N32*O32),0), "") | R32: =IFERROR(VLOOKUP(L32,#REF!,4,0),"") | S32: =IF(AND(Q32<>"",R32<>""),Q32*R32,"") | T32: =IF(E32*J32=0,"—",IF((Q32*M32*N32*O32)/E32<J32*0.9,"INSUFICIENTE -"&TEXT(ABS(((Q32*M32*N32*O32)/E32-J32)/J32)*100,"0")&"%",IF((Q32*M32*N32*O32)/E32>J32*1.31,"ACIMA +"&TEXT((((Q32*M32*N32*O32)/E32-J32)/J32)*100,"0")&"%","OK "&IF((Q32*M32*N32*O32)/E32>=J32,"+","")&TEXT((((Q32*M32*N32*O32)/E32-J32)/J32)*100,"0")&"%"))) -> #VALUE! | U32: =IF(E32*J32*M32=0,"",IF((Q32*M32*N32*O32)/E32<IF(IFERROR(VLOOKUP(D32,NBR!$C:$D,2,0),J32)=IFERROR(VLOOKUP(D32,NBR!$C:$F,4,0),J32),J32*0.9,IFERROR(VLOOKUP(D32,NBR!$C:$D,2,0),J32*0.9)),"COLOCAR +"&TEXT(ROUNDUP((E32*J32)/(M32*N32*O32),0)-Q32,"0")&" luminaria(s)",IF((Q32*M32*N32*O32)/E32>IF(IFERROR(VLOOKUP(D32,NBR!$C:$F,4,0),J32)=IFERROR(VLOOKUP(D32,NBR!$C:$D,2,0),J32),J32*1.2,IFERROR(VLOOKUP(D32,NBR!$C:$F,4,0),J32*1.2)),IF(Q32=1,"Reduzir potencia luminaria","RETIRAR -"&TEXT(Q32-ROUNDUP((E32*IF(IFERROR(VLOOKUP(D32,NBR!$C:$F,4,0),J32)=J32,J32*1.2,IFERROR(VLOOKUP(D32,NBR!$C:$F,4,0),J32*1.2)))/(M32*N32*O32),0),"0")&" luminaria(s)"),"OK"))) -> #VALUE! | V32: =IF(E32*M32=0,"",ROUND((Q32*M32*N32*O32)/E32,0)) -> #VALUE!
J33: =IFERROR(VLOOKUP(D33,NBR!$C:$E,3,0),"") | K33: =IF(E33*F33*I33=0,"",(4*E33)/((F33)*I33)) | M33: =IFERROR(VLOOKUP(L33,LAMPADAS!$A:$B,2,0),"") | P33: =IF(AND(E33<>"",J33<>"",M33<>"",N33<>"",O33<>"",N33<>0,O33<>0), ROUNDUP((E33*J33)/(M33*N33*O33),0), "") | R33: =IFERROR(VLOOKUP(L33,#REF!,4,0),"") | S33: =IF(AND(Q33<>"",R33<>""),Q33*R33,"") | T33: =IF(E33*J33=0,"—",IF((Q33*M33*N33*O33)/E33<J33*0.9,"INSUFICIENTE -"&TEXT(ABS(((Q33*M33*N33*O33)/E33-J33)/J33)*100,"0")&"%",IF((Q33*M33*N33*O33)/E33>J33*1.31,"ACIMA +"&TEXT((((Q33*M33*N33*O33)/E33-J33)/J33)*100,"0")&"%","OK "&IF((Q33*M33*N33*O33)/E33>=J33,"+","")&TEXT((((Q33*M33*N33*O33)/E33-J33)/J33)*100,"0")&"%"))) -> #VALUE! | U33: =IF(E33*J33*M33=0,"",IF((Q33*M33*N33*O33)/E33<IF(IFERROR(VLOOKUP(D33,NBR!$C:$D,2,0),J33)=IFERROR(VLOOKUP(D33,NBR!$C:$F,4,0),J33),J33*0.9,IFERROR(VLOOKUP(D33,NBR!$C:$D,2,0),J33*0.9)),"COLOCAR +"&TEXT(ROUNDUP((E33*J33)/(M33*N33*O33),0)-Q33,"0")&" luminaria(s)",IF((Q33*M33*N33*O33)/E33>IF(IFERROR(VLOOKUP(D33,NBR!$C:$F,4,0),J33)=IFERROR(VLOOKUP(D33,NBR!$C:$D,2,0),J33),J33*1.2,IFERROR(VLOOKUP(D33,NBR!$C:$F,4,0),J33*1.2)),IF(Q33=1,"Reduzir potencia luminaria","RETIRAR -"&TEXT(Q33-ROUNDUP((E33*IF(IFERROR(VLOOKUP(D33,NBR!$C:$F,4,0),J33)=J33,J33*1.2,IFERROR(VLOOKUP(D33,NBR!$C:$F,4,0),J33*1.2)))/(M33*N33*O33),0),"0")&" luminaria(s)"),"OK"))) -> #VALUE! | V33: =IF(E33*M33=0,"",ROUND((Q33*M33*N33*O33)/E33,0)) -> #VALUE!
J34: =IFERROR(VLOOKUP(D34,NBR!$C:$E,3,0),"") | K34: =IF(E34*F34*I34=0,"",(4*E34)/((F34)*I34)) | M34: =IFERROR(VLOOKUP(L34,LAMPADAS!$A:$B,2,0),"") | P34: =IF(AND(E34<>"",J34<>"",M34<>"",N34<>"",O34<>"",N34<>0,O34<>0), ROUNDUP((E34*J34)/(M34*N34*O34),0), "") | R34: =IFERROR(VLOOKUP(L34,#REF!,4,0),"") | S34: =IF(AND(Q34<>"",R34<>""),Q34*R34,"") | T34: =IF(E34*J34=0,"—",IF((Q34*M34*N34*O34)/E34<J34*0.9,"INSUFICIENTE -"&TEXT(ABS(((Q34*M34*N34*O34)/E34-J34)/J34)*100,"0")&"%",IF((Q34*M34*N34*O34)/E34>J34*1.31,"ACIMA +"&TEXT((((Q34*M34*N34*O34)/E34-J34)/J34)*100,"0")&"%","OK "&IF((Q34*M34*N34*O34)/E34>=J34,"+","")&TEXT((((Q34*M34*N34*O34)/E34-J34)/J34)*100,"0")&"%"))) -> #VALUE! | U34: =IF(E34*J34*M34=0,"",IF((Q34*M34*N34*O34)/E34<IF(IFERROR(VLOOKUP(D34,NBR!$C:$D,2,0),J34)=IFERROR(VLOOKUP(D34,NBR!$C:$F,4,0),J34),J34*0.9,IFERROR(VLOOKUP(D34,NBR!$C:$D,2,0),J34*0.9)),"COLOCAR +"&TEXT(ROUNDUP((E34*J34)/(M34*N34*O34),0)-Q34,"0")&" luminaria(s)",IF((Q34*M34*N34*O34)/E34>IF(IFERROR(VLOOKUP(D34,NBR!$C:$F,4,0),J34)=IFERROR(VLOOKUP(D34,NBR!$C:$D,2,0),J34),J34*1.2,IFERROR(VLOOKUP(D34,NBR!$C:$F,4,0),J34*1.2)),IF(Q34=1,"Reduzir potencia luminaria","RETIRAR -"&TEXT(Q34-ROUNDUP((E34*IF(IFERROR(VLOOKUP(D34,NBR!$C:$F,4,0),J34)=J34,J34*1.2,IFERROR(VLOOKUP(D34,NBR!$C:$F,4,0),J34*1.2)))/(M34*N34*O34),0),"0")&" luminaria(s)"),"OK"))) -> #VALUE! | V34: =IF(E34*M34=0,"",ROUND((Q34*M34*N34*O34)/E34,0)) -> #VALUE!
J35: =IFERROR(VLOOKUP(D35,NBR!$C:$E,3,0),"") | K35: =IF(E35*F35*I35=0,"",(4*E35)/((F35)*I35)) | M35: =IFERROR(VLOOKUP(L35,LAMPADAS!$A:$B,2,0),"") | P35: =IF(AND(E35<>"",J35<>"",M35<>"",N35<>"",O35<>"",N35<>0,O35<>0), ROUNDUP((E35*J35)/(M35*N35*O35),0), "") | R35: =IFERROR(VLOOKUP(L35,#REF!,4,0),"") | S35: =IF(AND(Q35<>"",R35<>""),Q35*R35,"") | T35: =IF(E35*J35=0,"—",IF((Q35*M35*N35*O35)/E35<J35*0.9,"INSUFICIENTE -"&TEXT(ABS(((Q35*M35*N35*O35)/E35-J35)/J35)*100,"0")&"%",IF((Q35*M35*N35*O35)/E35>J35*1.31,"ACIMA +"&TEXT((((Q35*M35*N35*O35)/E35-J35)/J35)*100,"0")&"%","OK "&IF((Q35*M35*N35*O35)/E35>=J35,"+","")&TEXT((((Q35*M35*N35*O35)/E35-J35)/J35)*100,"0")&"%"))) -> #VALUE! | U35: =IF(E35*J35*M35=0,"",IF((Q35*M35*N35*O35)/E35<IF(IFERROR(VLOOKUP(D35,NBR!$C:$D,2,0),J35)=IFERROR(VLOOKUP(D35,NBR!$C:$F,4,0),J35),J35*0.9,IFERROR(VLOOKUP(D35,NBR!$C:$D,2,0),J35*0.9)),"COLOCAR +"&TEXT(ROUNDUP((E35*J35)/(M35*N35*O35),0)-Q35,"0")&" luminaria(s)",IF((Q35*M35*N35*O35)/E35>IF(IFERROR(VLOOKUP(D35,NBR!$C:$F,4,0),J35)=IFERROR(VLOOKUP(D35,NBR!$C:$D,2,0),J35),J35*1.2,IFERROR(VLOOKUP(D35,NBR!$C:$F,4,0),J35*1.2)),IF(Q35=1,"Reduzir potencia luminaria","RETIRAR -"&TEXT(Q35-ROUNDUP((E35*IF(IFERROR(VLOOKUP(D35,NBR!$C:$F,4,0),J35)=J35,J35*1.2,IFERROR(VLOOKUP(D35,NBR!$C:$F,4,0),J35*1.2)))/(M35*N35*O35),0),"0")&" luminaria(s)"),"OK"))) -> #VALUE! | V35: =IF(E35*M35=0,"",ROUND((Q35*M35*N35*O35)/E35,0)) -> #VALUE!
J36: =IFERROR(VLOOKUP(D36,NBR!$C:$E,3,0),"") | K36: =IF(E36*F36*I36=0,"",(4*E36)/((F36)*I36)) | M36: =IFERROR(VLOOKUP(L36,LAMPADAS!$A:$B,2,0),"") | P36: =IF(AND(E36<>"",J36<>"",M36<>"",N36<>"",O36<>"",N36<>0,O36<>0), ROUNDUP((E36*J36)/(M36*N36*O36),0), "") | R36: =IFERROR(VLOOKUP(L36,#REF!,4,0),"") | S36: =IF(AND(Q36<>"",R36<>""),Q36*R36,"") | T36: =IF(E36*J36=0,"—",IF((Q36*M36*N36*O36)/E36<J36*0.9,"INSUFICIENTE -"&TEXT(ABS(((Q36*M36*N36*O36)/E36-J36)/J36)*100,"0")&"%",IF((Q36*M36*N36*O36)/E36>J36*1.31,"ACIMA +"&TEXT((((Q36*M36*N36*O36)/E36-J36)/J36)*100,"0")&"%","OK "&IF((Q36*M36*N36*O36)/E36>=J36,"+","")&TEXT((((Q36*M36*N36*O36)/E36-J36)/J36)*100,"0")&"%"))) -> #VALUE! | U36: =IF(E36*J36*M36=0,"",IF((Q36*M36*N36*O36)/E36<IF(IFERROR(VLOOKUP(D36,NBR!$C:$D,2,0),J36)=IFERROR(VLOOKUP(D36,NBR!$C:$F,4,0),J36),J36*0.9,IFERROR(VLOOKUP(D36,NBR!$C:$D,2,0),J36*0.9)),"COLOCAR +"&TEXT(ROUNDUP((E36*J36)/(M36*N36*O36),0)-Q36,"0")&" luminaria(s)",IF((Q36*M36*N36*O36)/E36>IF(IFERROR(VLOOKUP(D36,NBR!$C:$F,4,0),J36)=IFERROR(VLOOKUP(D36,NBR!$C:$D,2,0),J36),J36*1.2,IFERROR(VLOOKUP(D36,NBR!$C:$F,4,0),J36*1.2)),IF(Q36=1,"Reduzir potencia luminaria","RETIRAR -"&TEXT(Q36-ROUNDUP((E36*IF(IFERROR(VLOOKUP(D36,NBR!$C:$F,4,0),J36)=J36,J36*1.2,IFERROR(VLOOKUP(D36,NBR!$C:$F,4,0),J36*1.2)))/(M36*N36*O36),0),"0")&" luminaria(s)"),"OK"))) -> #VALUE! | V36: =IF(E36*M36=0,"",ROUND((Q36*M36*N36*O36)/E36,0)) -> #VALUE!
J37: =IFERROR(VLOOKUP(D37,NBR!$C:$E,3,0),"") | K37: =IF(E37*F37*I37=0,"",(4*E37)/((F37)*I37)) | M37: =IFERROR(VLOOKUP(L37,LAMPADAS!$A:$B,2,0),"") | P37: =IF(AND(E37<>"",J37<>"",M37<>"",N37<>"",O37<>"",N37<>0,O37<>0), ROUNDUP((E37*J37)/(M37*N37*O37),0), "") | R37: =IFERROR(VLOOKUP(L37,#REF!,4,0),"") | S37: =IF(AND(Q37<>"",R37<>""),Q37*R37,"") | T37: =IF(E37*J37=0,"—",IF((Q37*M37*N37*O37)/E37<J37*0.9,"INSUFICIENTE -"&TEXT(ABS(((Q37*M37*N37*O37)/E37-J37)/J37)*100,"0")&"%",IF((Q37*M37*N37*O37)/E37>J37*1.31,"ACIMA +"&TEXT((((Q37*M37*N37*O37)/E37-J37)/J37)*100,"0")&"%","OK "&IF((Q37*M37*N37*O37)/E37>=J37,"+","")&TEXT((((Q37*M37*N37*O37)/E37-J37)/J37)*100,"0")&"%"))) -> #VALUE! | U37: =IF(E37*J37*M37=0,"",IF((Q37*M37*N37*O37)/E37<IF(IFERROR(VLOOKUP(D37,NBR!$C:$D,2,0),J37)=IFERROR(VLOOKUP(D37,NBR!$C:$F,4,0),J37),J37*0.9,IFERROR(VLOOKUP(D37,NBR!$C:$D,2,0),J37*0.9)),"COLOCAR +"&TEXT(ROUNDUP((E37*J37)/(M37*N37*O37),0)-Q37,"0")&" luminaria(s)",IF((Q37*M37*N37*O37)/E37>IF(IFERROR(VLOOKUP(D37,NBR!$C:$F,4,0),J37)=IFERROR(VLOOKUP(D37,NBR!$C:$D,2,0),J37),J37*1.2,IFERROR(VLOOKUP(D37,NBR!$C:$F,4,0),J37*1.2)),IF(Q37=1,"Reduzir potencia luminaria","RETIRAR -"&TEXT(Q37-ROUNDUP((E37*IF(IFERROR(VLOOKUP(D37,NBR!$C:$F,4,0),J37)=J37,J37*1.2,IFERROR(VLOOKUP(D37,NBR!$C:$F,4,0),J37*1.2)))/(M37*N37*O37),0),"0")&" luminaria(s)"),"OK"))) -> #VALUE! | V37: =IF(E37*M37=0,"",ROUND((Q37*M37*N37*O37)/E37,0)) -> #VALUE!
... J49: =IFERROR(VLOOKUP(D49,NBR!$C:$E,3,0),"") | K49: =IF(E49*F49*I49=0,"",(4*E49)/((F49)*I49)) | M49: =IFERROR(VLOOKUP(L49,LAMPADAS!$A:$B,2,0),"") | P49: =IF(AND(E49<>"",J49<>"",M49<>"",N49<>"",O49<>"",N49<>0,O49<>0), ROUNDUP((E49*J49)/(M49*N49*O49),0), "") | R49: =IFERROR(VLOOKUP(L49,#REF!,4,0),"") | S49: =IF(AND(Q49<>"",R49<>""),Q49*R49,"") | T49: =IF(E49*J49=0,"—",IF((Q49*M49*N49*O49)/E49<J49*0.9,"INSUFICIENTE -"&TEXT(ABS(((Q49*M49*N49*O49)/E49-J49)/J49)*100,"0")&"%",IF((Q49*M49*N49*O49)/E49>J49*1.31,"ACIMA +"&TEXT((((Q49*M49*N49*O49)/E49-J49)/J49)*100,"0")&"%","OK "&IF((Q49*M49*N49*O49)/E49>=J49,"+","")&TEXT((((Q49*M49*N49*O49)/E49-J49)/J49)*100,"0")&"%"))) -> #VALUE! | U49: =IF(E49*J49*M49=0,"",IF((Q49*M49*N49*O49)/E49<IF(IFERROR(VLOOKUP(D49,NBR!$C:$D,2,0),J49)=IFERROR(VLOOKUP(D49,NBR!$C:$F,4,0),J49),J49*0.9,IFERROR(VLOOKUP(D49,NBR!$C:$D,2,0),J49*0.9)),"COLOCAR +"&TEXT(ROUNDUP((E49*J49)/(M49*N49*O49),0)-Q49,"0")&" luminaria(s)",IF((Q49*M49*N49*O49)/E49>IF(IFERROR(VLOOKUP(D49,NBR!$C:$F,4,0),J49)=IFERROR(VLOOKUP(D49,NBR!$C:$D,2,0),J49),J49*1.2,IFERROR(VLOOKUP(D49,NBR!$C:$F,4,0),J49*1.2)),IF(Q49=1,"Reduzir potencia luminaria","RETIRAR -"&TEXT(Q49-ROUNDUP((E49*IF(IFERROR(VLOOKUP(D49,NBR!$C:$F,4,0),J49)=J49,J49*1.2,IFERROR(VLOOKUP(D49,NBR!$C:$F,4,0),J49*1.2)))/(M49*N49*O49),0),"0")&" luminaria(s)"),"OK"))) -> #VALUE! | V49: =IF(E49*M49=0,"",ROUND((Q49*M49*N49*O49)/E49,0)) -> #VALUE!
E50: =IF(G50*H50=0,"",ROUND(G50*H50,2)) | J50: =IFERROR(VLOOKUP(D50,NBR!$C:$E,3,0),"") | K50: =IF(E50*F50*I50=0,"",(4*E50)/((F50)*I50)) -> #VALUE! | M50: =IFERROR(VLOOKUP(L50,LAMPADAS!$A:$B,2,0),"") | P50: =IF(AND(E50<>"",J50<>"",M50<>"",N50<>"",O50<>"",N50<>0,O50<>0), ROUNDUP((E50*J50)/(M50*N50*O50),0), "") | R50: =IFERROR(VLOOKUP(L50,#REF!,4,0),"") | S50: =IF(AND(Q50<>"",R50<>""),Q50*R50,"") | T50: =IF(E50*J50=0,"—",IF((Q50*M50*N50*O50)/E50<J50*0.9,"INSUFICIENTE -"&TEXT(ABS(((Q50*M50*N50*O50)/E50-J50)/J50)*100,"0")&"%",IF((Q50*M50*N50*O50)/E50>J50*1.31,"ACIMA +"&TEXT((((Q50*M50*N50*O50)/E50-J50)/J50)*100,"0")&"%","OK "&IF((Q50*M50*N50*O50)/E50>=J50,"+","")&TEXT((((Q50*M50*N50*O50)/E50-J50)/J50)*100,"0")&"%"))) -> #VALUE! | U50: =IF(E50*J50*M50=0,"",IF((Q50*M50*N50*O50)/E50<IF(IFERROR(VLOOKUP(D50,NBR!$C:$D,2,0),J50)=IFERROR(VLOOKUP(D50,NBR!$C:$F,4,0),J50),J50*0.9,IFERROR(VLOOKUP(D50,NBR!$C:$D,2,0),J50*0.9)),"COLOCAR +"&TEXT(ROUNDUP((E50*J50)/(M50*N50*O50),0)-Q50,"0")&" luminaria(s)",IF((Q50*M50*N50*O50)/E50>IF(IFERROR(VLOOKUP(D50,NBR!$C:$F,4,0),J50)=IFERROR(VLOOKUP(D50,NBR!$C:$D,2,0),J50),J50*1.2,IFERROR(VLOOKUP(D50,NBR!$C:$F,4,0),J50*1.2)),IF(Q50=1,"Reduzir potencia luminaria","RETIRAR -"&TEXT(Q50-ROUNDUP((E50*IF(IFERROR(VLOOKUP(D50,NBR!$C:$F,4,0),J50)=J50,J50*1.2,IFERROR(VLOOKUP(D50,NBR!$C:$F,4,0),J50*1.2)))/(M50*N50*O50),0),"0")&" luminaria(s)"),"OK"))) -> #VALUE! | V50: =IF(E50*M50=0,"",ROUND((Q50*M50*N50*O50)/E50,0)) -> #VALUE!
E51: =IF(G51*H51=0,"",ROUND(G51*H51,2)) | J51: =IFERROR(VLOOKUP(D51,NBR!$C:$E,3,0),"") | K51: =IF(E51*F51*I51=0,"",(4*E51)/((F51)*I51)) -> #VALUE! | M51: =IFERROR(VLOOKUP(L51,LAMPADAS!$A:$B,2,0),"") | P51: =IF(AND(E51<>"",J51<>"",M51<>"",N51<>"",O51<>"",N51<>0,O51<>0), ROUNDUP((E51*J51)/(M51*N51*O51),0), "") | R51: =IFERROR(VLOOKUP(L51,#REF!,4,0),"") | S51: =IF(AND(Q51<>"",R51<>""),Q51*R51,"") | T51: =IF(E51*J51=0,"—",IF((Q51*M51*N51*O51)/E51<J51*0.9,"INSUFICIENTE -"&TEXT(ABS(((Q51*M51*N51*O51)/E51-J51)/J51)*100,"0")&"%",IF((Q51*M51*N51*O51)/E51>J51*1.31,"ACIMA +"&TEXT((((Q51*M51*N51*O51)/E51-J51)/J51)*100,"0")&"%","OK "&IF((Q51*M51*N51*O51)/E51>=J51,"+","")&TEXT((((Q51*M51*N51*O51)/E51-J51)/J51)*100,"0")&"%"))) -> #VALUE! | U51: =IF(E51*J51*M51=0,"",IF((Q51*M51*N51*O51)/E51<IF(IFERROR(VLOOKUP(D51,NBR!$C:$D,2,0),J51)=IFERROR(VLOOKUP(D51,NBR!$C:$F,4,0),J51),J51*0.9,IFERROR(VLOOKUP(D51,NBR!$C:$D,2,0),J51*0.9)),"COLOCAR +"&TEXT(ROUNDUP((E51*J51)/(M51*N51*O51),0)-Q51,"0")&" luminaria(s)",IF((Q51*M51*N51*O51)/E51>IF(IFERROR(VLOOKUP(D51,NBR!$C:$F,4,0),J51)=IFERROR(VLOOKUP(D51,NBR!$C:$D,2,0),J51),J51*1.2,IFERROR(VLOOKUP(D51,NBR!$C:$F,4,0),J51*1.2)),IF(Q51=1,"Reduzir potencia luminaria","RETIRAR -"&TEXT(Q51-ROUNDUP((E51*IF(IFERROR(VLOOKUP(D51,NBR!$C:$F,4,0),J51)=J51,J51*1.2,IFERROR(VLOOKUP(D51,NBR!$C:$F,4,0),J51*1.2)))/(M51*N51*O51),0),"0")&" luminaria(s)"),"OK"))) -> #VALUE! | V51: =IF(E51*M51=0,"",ROUND((Q51*M51*N51*O51)/E51,0)) -> #VALUE!
E52: =IF(G52*H52=0,"",ROUND(G52*H52,2)) | J52: =IFERROR(VLOOKUP(D52,NBR!$C:$E,3,0),"") | K52: =IF(E52*F52*I52=0,"",(4*E52)/((F52)*I52)) -> #VALUE! | M52: =IFERROR(VLOOKUP(L52,LAMPADAS!$A:$B,2,0),"") | P52: =IF(AND(E52<>"",J52<>"",M52<>"",N52<>"",O52<>"",N52<>0,O52<>0), ROUNDUP((E52*J52)/(M52*N52*O52),0), "") | R52: =IFERROR(VLOOKUP(L52,#REF!,4,0),"") | S52: =IF(AND(Q52<>"",R52<>""),Q52*R52,"") | T52: =IF(E52*J52=0,"—",IF((Q52*M52*N52*O52)/E52<J52*0.9,"INSUFICIENTE -"&TEXT(ABS(((Q52*M52*N52*O52)/E52-J52)/J52)*100,"0")&"%",IF((Q52*M52*N52*O52)/E52>J52*1.31,"ACIMA +"&TEXT((((Q52*M52*N52*O52)/E52-J52)/J52)*100,"0")&"%","OK "&IF((Q52*M52*N52*O52)/E52>=J52,"+","")&TEXT((((Q52*M52*N52*O52)/E52-J52)/J52)*100,"0")&"%"))) -> #VALUE! | U52: =IF(E52*J52*M52=0,"",IF((Q52*M52*N52*O52)/E52<IF(IFERROR(VLOOKUP(D52,NBR!$C:$D,2,0),J52)=IFERROR(VLOOKUP(D52,NBR!$C:$F,4,0),J52),J52*0.9,IFERROR(VLOOKUP(D52,NBR!$C:$D,2,0),J52*0.9)),"COLOCAR +"&TEXT(ROUNDUP((E52*J52)/(M52*N52*O52),0)-Q52,"0")&" luminaria(s)",IF((Q52*M52*N52*O52)/E52>IF(IFERROR(VLOOKUP(D52,NBR!$C:$F,4,0),J52)=IFERROR(VLOOKUP(D52,NBR!$C:$D,2,0),J52),J52*1.2,IFERROR(VLOOKUP(D52,NBR!$C:$F,4,0),J52*1.2)),IF(Q52=1,"Reduzir potencia luminaria","RETIRAR -"&TEXT(Q52-ROUNDUP((E52*IF(IFERROR(VLOOKUP(D52,NBR!$C:$F,4,0),J52)=J52,J52*1.2,IFERROR(VLOOKUP(D52,NBR!$C:$F,4,0),J52*1.2)))/(M52*N52*O52),0),"0")&" luminaria(s)"),"OK"))) -> #VALUE! | V52: =IF(E52*M52=0,"",ROUND((Q52*M52*N52*O52)/E52,0)) -> #VALUE!
E53: =IF(G53*H53=0,"",ROUND(G53*H53,2)) | J53: =IFERROR(VLOOKUP(D53,NBR!$C:$E,3,0),"") | K53: =IF(E53*F53*I53=0,"",(4*E53)/((F53)*I53)) -> #VALUE! | M53: =IFERROR(VLOOKUP(L53,LAMPADAS!$A:$B,2,0),"") | P53: =IF(AND(E53<>"",J53<>"",M53<>"",N53<>"",O53<>"",N53<>0,O53<>0), ROUNDUP((E53*J53)/(M53*N53*O53),0), "") | R53: =IFERROR(VLOOKUP(L53,#REF!,4,0),"") | S53: =IF(AND(Q53<>"",R53<>""),Q53*R53,"") | T53: =IF(E53*J53=0,"—",IF((Q53*M53*N53*O53)/E53<J53*0.9,"INSUFICIENTE -"&TEXT(ABS(((Q53*M53*N53*O53)/E53-J53)/J53)*100,"0")&"%",IF((Q53*M53*N53*O53)/E53>J53*1.31,"ACIMA +"&TEXT((((Q53*M53*N53*O53)/E53-J53)/J53)*100,"0")&"%","OK "&IF((Q53*M53*N53*O53)/E53>=J53,"+","")&TEXT((((Q53*M53*N53*O53)/E53-J53)/J53)*100,"0")&"%"))) -> #VALUE! | U53: =IF(E53*J53*M53=0,"",IF((Q53*M53*N53*O53)/E53<IF(IFERROR(VLOOKUP(D53,NBR!$C:$D,2,0),J53)=IFERROR(VLOOKUP(D53,NBR!$C:$F,4,0),J53),J53*0.9,IFERROR(VLOOKUP(D53,NBR!$C:$D,2,0),J53*0.9)),"COLOCAR +"&TEXT(ROUNDUP((E53*J53)/(M53*N53*O53),0)-Q53,"0")&" luminaria(s)",IF((Q53*M53*N53*O53)/E53>IF(IFERROR(VLOOKUP(D53,NBR!$C:$F,4,0),J53)=IFERROR(VLOOKUP(D53,NBR!$C:$D,2,0),J53),J53*1.2,IFERROR(VLOOKUP(D53,NBR!$C:$F,4,0),J53*1.2)),IF(Q53=1,"Reduzir potencia luminaria","RETIRAR -"&TEXT(Q53-ROUNDUP((E53*IF(IFERROR(VLOOKUP(D53,NBR!$C:$F,4,0),J53)=J53,J53*1.2,IFERROR(VLOOKUP(D53,NBR!$C:$F,4,0),J53*1.2)))/(M53*N53*O53),0),"0")&" luminaria(s)"),"OK"))) -> #VALUE! | V53: =IF(E53*M53=0,"",ROUND((Q53*M53*N53*O53)/E53,0)) -> #VALUE!
E54: =IF(G54*H54=0,"",ROUND(G54*H54,2)) | J54: =IFERROR(VLOOKUP(D54,NBR!$C:$E,3,0),"") | K54: =IF(E54*F54*I54=0,"",(4*E54)/((F54)*I54)) -> #VALUE! | M54: =IFERROR(VLOOKUP(L54,LAMPADAS!$A:$B,2,0),"") | P54: =IF(AND(E54<>"",J54<>"",M54<>"",N54<>"",O54<>"",N54<>0,O54<>0), ROUNDUP((E54*J54)/(M54*N54*O54),0), "") | R54: =IFERROR(VLOOKUP(L54,#REF!,4,0),"") | S54: =IF(AND(Q54<>"",R54<>""),Q54*R54,"") | T54: =IF(E54*J54=0,"—",IF((Q54*M54*N54*O54)/E54<J54*0.9,"INSUFICIENTE -"&TEXT(ABS(((Q54*M54*N54*O54)/E54-J54)/J54)*100,"0")&"%",IF((Q54*M54*N54*O54)/E54>J54*1.31,"ACIMA +"&TEXT((((Q54*M54*N54*O54)/E54-J54)/J54)*100,"0")&"%","OK "&IF((Q54*M54*N54*O54)/E54>=J54,"+","")&TEXT((((Q54*M54*N54*O54)/E54-J54)/J54)*100,"0")&"%"))) -> #VALUE! | U54: =IF(E54*J54*M54=0,"",IF((Q54*M54*N54*O54)/E54<IF(IFERROR(VLOOKUP(D54,NBR!$C:$D,2,0),J54)=IFERROR(VLOOKUP(D54,NBR!$C:$F,4,0),J54),J54*0.9,IFERROR(VLOOKUP(D54,NBR!$C:$D,2,0),J54*0.9)),"COLOCAR +"&TEXT(ROUNDUP((E54*J54)/(M54*N54*O54),0)-Q54,"0")&" luminaria(s)",IF((Q54*M54*N54*O54)/E54>IF(IFERROR(VLOOKUP(D54,NBR!$C:$F,4,0),J54)=IFERROR(VLOOKUP(D54,NBR!$C:$D,2,0),J54),J54*1.2,IFERROR(VLOOKUP(D54,NBR!$C:$F,4,0),J54*1.2)),IF(Q54=1,"Reduzir potencia luminaria","RETIRAR -"&TEXT(Q54-ROUNDUP((E54*IF(IFERROR(VLOOKUP(D54,NBR!$C:$F,4,0),J54)=J54,J54*1.2,IFERROR(VLOOKUP(D54,NBR!$C:$F,4,0),J54*1.2)))/(M54*N54*O54),0),"0")&" luminaria(s)"),"OK"))) -> #VALUE! | V54: =IF(E54*M54=0,"",ROUND((Q54*M54*N54*O54)/E54,0)) -> #VALUE!
E55: =IF(G55*H55=0,"",ROUND(G55*H55,2)) | J55: =IFERROR(VLOOKUP(D55,NBR!$C:$E,3,0),"") | K55: =IF(E55*F55*I55=0,"",(4*E55)/((F55)*I55)) -> #VALUE! | M55: =IFERROR(VLOOKUP(L55,LAMPADAS!$A:$B,2,0),"") | P55: =IF(AND(E55<>"",J55<>"",M55<>"",N55<>"",O55<>"",N55<>0,O55<>0), ROUNDUP((E55*J55)/(M55*N55*O55),0), "") | R55: =IFERROR(VLOOKUP(L55,#REF!,4,0),"") | S55: =IF(AND(Q55<>"",R55<>""),Q55*R55,"") | T55: =IF(E55*J55=0,"—",IF((Q55*M55*N55*O55)/E55<J55*0.9,"INSUFICIENTE -"&TEXT(ABS(((Q55*M55*N55*O55)/E55-J55)/J55)*100,"0")&"%",IF((Q55*M55*N55*O55)/E55>J55*1.31,"ACIMA +"&TEXT((((Q55*M55*N55*O55)/E55-J55)/J55)*100,"0")&"%","OK "&IF((Q55*M55*N55*O55)/E55>=J55,"+","")&TEXT((((Q55*M55*N55*O55)/E55-J55)/J55)*100,"0")&"%"))) -> #VALUE! | U55: =IF(E55*J55*M55=0,"",IF((Q55*M55*N55*O55)/E55<IF(IFERROR(VLOOKUP(D55,NBR!$C:$D,2,0),J55)=IFERROR(VLOOKUP(D55,NBR!$C:$F,4,0),J55),J55*0.9,IFERROR(VLOOKUP(D55,NBR!$C:$D,2,0),J55*0.9)),"COLOCAR +"&TEXT(ROUNDUP((E55*J55)/(M55*N55*O55),0)-Q55,"0")&" luminaria(s)",IF((Q55*M55*N55*O55)/E55>IF(IFERROR(VLOOKUP(D55,NBR!$C:$F,4,0),J55)=IFERROR(VLOOKUP(D55,NBR!$C:$D,2,0),J55),J55*1.2,IFERROR(VLOOKUP(D55,NBR!$C:$F,4,0),J55*1.2)),IF(Q55=1,"Reduzir potencia luminaria","RETIRAR -"&TEXT(Q55-ROUNDUP((E55*IF(IFERROR(VLOOKUP(D55,NBR!$C:$F,4,0),J55)=J55,J55*1.2,IFERROR(VLOOKUP(D55,NBR!$C:$F,4,0),J55*1.2)))/(M55*N55*O55),0),"0")&" luminaria(s)"),"OK"))) -> #VALUE! | V55: =IF(E55*M55=0,"",ROUND((Q55*M55*N55*O55)/E55,0)) -> #VALUE!
...

Sheet LAMPADAS
A1: LUMINARIAS DO PROJETO — Adicione novas linhas na tabela para incluir luminarias
A2: DESCRICAO | B2: FLUXO (lm) | C2: TIPO | D2: POTENCIA (W) | E2: EFICACIA (lm/W)
A3: Tubular fluorescente T5 14W | B3: 1200 | C3: Fluorescente | D3: 14 | E3: 85.7
A4: Tubular fluorescente T5 28W | B4: 2600 | C4: Fluorescente | D4: 28 | E4: 92.9
A5: Vapor metalico 35W | B5: 3700 | C5: Vapor metalico | D5: 35 | E5: 105.7
A6: Vapor metalico 70W | B6: 5700 | C6: Vapor metalico | D6: 70 | E6: 81.4
A7: Vapor metalico 150W | B7: 12900 | C7: Vapor metalico | D7: 150 | E7: 86
A8: Vapor metalico 250W | B8: 17000 | C8: Vapor metalico | D8: 250 | E8: 68
A9: Vapor metalico 400W | B9: 32000 | C9: Vapor metalico | D9: 400 | E9: 80
A10: Placa LED 10W | B10: 700 | C10: Placa LED embutir | D10: 10 | E10: 70
A11: Placa LED 14W | B11: 1000 | C11: Placa LED embutir | D11: 14 | E11: 71.4
A12: Placa LED 20W | B12: 1700 | C12: Placa LED embutir | D12: 20 | E12: 85
A13: Placa LED 32W | B13: 2800 | C13: Placa LED embutir | D13: 32 | E13: 87.5
A14: Placa LED 40W | B14: 3900 | C14: Placa LED embutir | D14: 40 | E14: 97.5
... A36: Luminaria Publica 250W (Philips BGP323) | B36: 27775 | C36: Iluminacao publica | D36: 250 | E36: 111.1

Sheet NBR
A1: TABELA NBR — ILUMINANCIA DE AMBIENTES (NBR 8995-1:2013 + NBR 5413:1992)
A2: Referencia para dropdown da aba AMBIENTES. Azul=8995-1 (Em unico). Verde=5413 (min/MED/max).
A3: NORMA | B3: GRUPO | C3: ATIVIDADE / AMBIENTE | D3: Em MIN | E3: Em MED | F3: Em MAX
A4: NBR 8995-1:2013 — Iluminancia Mantida (Em unico)
A5: 1. Areas gerais
A6: NBR 8995-1 | B6: 1. Areas gerais | C6: Saguao de entrada | D6: 100 | E6: 100 | F6: 100
A7: NBR 8995-1 | B7: 1. Areas gerais | C7: Sala de espera | D7: 200 | E7: 200 | F7: 200
A8: NBR 8995-1 | B8: 1. Areas gerais | C8: Circulacao e corredores | D8: 100 | E8: 100 | F8: 100
A9: NBR 8995-1 | B9: 1. Areas gerais | C9: Escadas e escadas rolantes | D9: 150 | E9: 150 | F9: 150
A10: NBR 8995-1 | B10: 1. Areas gerais | C10: Rampas de carregamento | D10: 150 | E10: 150 | F10: 150
A11: NBR 8995-1 | B11: 1. Areas gerais | C11: Refeitorio / Cantinas | D11: 200 | E11: 200 | F11: 200
A12: NBR 8995-1 | B12: 1. Areas gerais | C12: Salas de descanso | D12: 100 | E12: 100 | F12: 100
A13: NBR 8995-1 | B13: 1. Areas gerais | C13: Salas para exercicios fisicos | D13: 300 | E13: 300 | F13: 300
A14: NBR 8995-1 | B14: 1. Areas gerais | C14: Vestiarios, banheiros, toaletes | D14: 200 | E14: 200 | F14: 200
A15: NBR 8995-1 | B15: 1. Areas gerais | C15: Enfermaria | D15: 500 | E15: 500 | F15: 500
A16: NBR 8995-1 | B16: 1. Areas gerais | C16: Salas para atendimento medico | D16: 500 | E16: 500 | F16: 500
A17: NBR 8995-1 | B17: 1. Areas gerais | C17: Deposito, estoques, camara fria | D17: 100 | E17: 100 | F17: 100
... A19: NBR 8995-1 | B19: 1. Areas gerais | C19: Estacao de controle | D19: 150 | E19: 150 | F19: 150
A20: 22. Escritorios
A21: NBR 8995-1 | B21: 22. Escritorios | C21: Arquivamento, copia, circulacao | D21: 300 | E21: 300 | F21: 300
A22: NBR 8995-1 | B22: 22. Escritorios | C22: Escrever, teclar, ler, processar dados | D22: 500 | E22: 500 | F22: 500
A23: NBR 8995-1 | B23: 22. Escritorios | C23: Desenho tecnico | D23: 750 | E23: 750 | F23: 750
A24: NBR 8995-1 | B24: 22. Escritorios | C24: Estacoes CAD | D24: 500 | E24: 500 | F24: 500
A25: NBR 8995-1 | B25: 22. Escritorios | C25: Salas de reuniao e conferencia | D25: 500 | E25: 500 | F25: 500
A26: NBR 8995-1 | B26: 22. Escritorios | C26: Recepcao escritorio | D26: 300 | E26: 300 | F26: 300
A27: NBR 8995-1 | B27: 22. Escritorios | C27: Arquivos escritorio | D27: 200 | E27: 200 | F27: 200
A28: 23. Varejo
A29: NBR 8995-1 | B29: 23. Varejo | C29: Area de vendas pequena | D29: 300 | E29: 300 | F29: 300
A30: NBR 8995-1 | B30: 23. Varejo | C30: Area de vendas grande | D30: 500 | E30: 500 | F30: 500
A31: NBR 8995-1 | B31: 23. Varejo | C31: Area da caixa registradora | D31: 500 | E31: 500 | F31: 500
A32: 24. Restaurantes/Hoteis
A33: NBR 8995-1 | B33: 24. Restaurantes/Hoteis | C33: Recepcao / caixa / portaria hotel | D33: 300 | E33: 300 | F33: 300
A34: NBR 8995-1 | B34: 24. Restaurantes/Hoteis | C34: Cozinha hotel | D34: 500 | E34: 500 | F34: 500
A35: NBR 8995-1 | B35: 24. Restaurantes/Hoteis | C35: Restaurante / sala de jantar | D35: 200 | E35: 200 | F35: 200
A36: NBR 8995-1 | B36: 24. Restaurantes/Hoteis | C36: Salas de conferencias hotel | D36: 500 | E36: 500 | F36: 500
A37: NBR 8995-1 | B37: 24. Restaurantes/Hoteis | C37: Corredores hotel | D37: 100 | E37: 100 | F37: 100
A38: 25. Entretenimento
A39: NBR 8995-1 | B39: 25. Entretenimento | C39: Teatros e salas de concerto | D39: 200 | E39: 200 | F39: 200
A40: NBR 8995-1 | B40: 25. Entretenimento | C40: Salas de ensaio / camarins | D40: 300 | E40: 300 | F40: 300
A41: NBR 8995-1 | B41: 25. Entretenimento | C41: Museus (geral) | D41: 300 | E41: 300 | F41: 300
...

Sheet CONSULTA
A1: CONSULTA RAPIDA — LUMINOTECNICO
A3: BLOCO 1 — FATOR DE MANUTENCAO (FM)
A4: TIPO DE AMBIENTE | B4: FM | C4: DESCRICAO
A5: Limpo | B5: 0.9 | C5: Manutencao regular, pouca poeira
A6: Medio | B6: 0.8 | C6: Manutencao periodica — uso geral
A7: Sujo | B7: 0.6 | C7: Manutencao irregular, ambientes industriais
A9: BLOCO 2 — FATOR DE UTILIZACAO (FU) — Estimativa por tipo de ambiente
A10: TIPO DE AMBIENTE | B10: FU ESTIMADO | C10: OBSERVACAO
A11: Escritorio / sala comum | B11: 0.8 | C11: Teto branco, paredes claras
A12: Corredor / circulacao | B12: 0.7 | C12: Paredes medias, teto branco
A13: Deposito / almoxarifado | B13: 0.6 | C13: Paredes e teto medios/escuros
A14: Galpao / area industrial | B14: 0.65 | C14: Po e sujeira reduzem reflexao
A15: Banheiro / lavatório | B15: 0.75 | C15: Azulejo reflete bem
A16: Sala de reuniao / auditorio | B16: 0.75 | C16: Teto e paredes medios
